self=$$;  ( mysqldump --single-transaction --quick --lock-tables=false -u _f3e7bb7e772b3608 -p********** _f3e7bb7e772b3608 -h 127.0.0.1 -P 3306   || kill $self )  | /usr/bin/gzip >> ./arun/private/backups/20231120_120002-arun-database.sql.gz

Backup Summary for arun at 2023-11-20 12:00:02.803958
Config  : ./arun/private/backups/20231120_120002-arun-site_config_backup.json 94.0B
Database: ./arun/private/backups/20231120_120002-arun-database.sql.gz         259.8KiB
Backup for Site arun has been successfully completed
Backup failed for Site skyai. Database or site_config.json may be corrupted
Traceback (most recent call last):
  File "apps/frappe/frappe/commands/site.py", line 718, in backup
    odb = scheduled_backup(
  File "apps/frappe/frappe/utils/backups.py", line 532, in scheduled_backup
    odb = new_backup(
  File "apps/frappe/frappe/utils/backups.py", line 566, in new_backup
    odb = BackupGenerator(
  File "apps/frappe/frappe/utils/backups.py", line 84, in __init__
    self.setup_backup_tables()
  File "apps/frappe/frappe/utils/backups.py", line 116, in setup_backup_tables
    existing_tables = frappe.db.get_tables()
  File "apps/frappe/frappe/database/mariadb/database.py", line 439, in get_tables
    frappe.qb.from_(information_schema.tables)
  File "apps/frappe/frappe/query_builder/utils.py", line 87, in execute_query
    result = frappe.db.sql(query, params, *args, **kwargs)  # nosemgrep
  File "apps/frappe/frappe/database/database.py", line 201, in sql
    self.connect()
  File "apps/frappe/frappe/database/database.py", line 115, in connect
    self._conn = self.get_connection()
  File "apps/frappe/frappe/database/mariadb/database.py", line 98, in get_connection
    conn = self._get_connection()
  File "apps/frappe/frappe/database/mariadb/database.py", line 104, in _get_connection
    return self.create_connection()
  File "apps/frappe/frappe/database/mariadb/database.py", line 107, in create_connection
    return pymysql.connect(**self.get_connection_settings())
  File "env/lib/python3.10/site-packages/pymysql/connections.py", line 352, in __init__
    self.connect()
  File "env/lib/python3.10/site-packages/pymysql/connections.py", line 636, in connect
    self._request_authentication()
  File "env/lib/python3.10/site-packages/pymysql/connections.py", line 911, in _request_authentication
    auth_packet = self._read_packet()
  File "env/lib/python3.10/site-packages/pymysql/connections.py", line 729, in _read_packet
    packet.raise_for_error()
  File "env/lib/python3.10/site-packages/pymysql/protocol.py", line 221, in raise_for_error
    err.raise_mysql_exception(self._data)
  File "env/lib/python3.10/site-packages/pymysql/err.py", line 143, in raise_mysql_exception
    raise errorclass(errno, errval)
pymysql.err.OperationalError: (1698, "Access denied for user '_a4db896e4fe6001d'@'localhost'")

Backup failed for Site skyai2. Database or site_config.json may be corrupted
Traceback (most recent call last):
  File "apps/frappe/frappe/commands/site.py", line 718, in backup
    odb = scheduled_backup(
  File "apps/frappe/frappe/utils/backups.py", line 532, in scheduled_backup
    odb = new_backup(
  File "apps/frappe/frappe/utils/backups.py", line 566, in new_backup
    odb = BackupGenerator(
  File "apps/frappe/frappe/utils/backups.py", line 84, in __init__
    self.setup_backup_tables()
  File "apps/frappe/frappe/utils/backups.py", line 116, in setup_backup_tables
    existing_tables = frappe.db.get_tables()
  File "apps/frappe/frappe/database/mariadb/database.py", line 439, in get_tables
    frappe.qb.from_(information_schema.tables)
  File "apps/frappe/frappe/query_builder/utils.py", line 87, in execute_query
    result = frappe.db.sql(query, params, *args, **kwargs)  # nosemgrep
  File "apps/frappe/frappe/database/database.py", line 201, in sql
    self.connect()
  File "apps/frappe/frappe/database/database.py", line 115, in connect
    self._conn = self.get_connection()
  File "apps/frappe/frappe/database/mariadb/database.py", line 98, in get_connection
    conn = self._get_connection()
  File "apps/frappe/frappe/database/mariadb/database.py", line 104, in _get_connection
    return self.create_connection()
  File "apps/frappe/frappe/database/mariadb/database.py", line 107, in create_connection
    return pymysql.connect(**self.get_connection_settings())
  File "env/lib/python3.10/site-packages/pymysql/connections.py", line 352, in __init__
    self.connect()
  File "env/lib/python3.10/site-packages/pymysql/connections.py", line 636, in connect
    self._request_authentication()
  File "env/lib/python3.10/site-packages/pymysql/connections.py", line 911, in _request_authentication
    auth_packet = self._read_packet()
  File "env/lib/python3.10/site-packages/pymysql/connections.py", line 729, in _read_packet
    packet.raise_for_error()
  File "env/lib/python3.10/site-packages/pymysql/protocol.py", line 221, in raise_for_error
    err.raise_mysql_exception(self._data)
  File "env/lib/python3.10/site-packages/pymysql/err.py", line 143, in raise_mysql_exception
    raise errorclass(errno, errval)
pymysql.err.OperationalError: (1698, "Access denied for user '_a4db896e4fe6001d'@'localhost'")

self=$$;  ( mysqldump --single-transaction --quick --lock-tables=false -u _f3e7bb7e772b3608 -p********** _f3e7bb7e772b3608 -h 127.0.0.1 -P 3306   || kill $self )  | /usr/bin/gzip >> ./arun/private/backups/20231120_180002-arun-database.sql.gz

Backup Summary for arun at 2023-11-20 18:00:03.727297
Config  : ./arun/private/backups/20231120_180002-arun-site_config_backup.json 94.0B
Database: ./arun/private/backups/20231120_180002-arun-database.sql.gz         1.0MiB
Backup for Site arun has been successfully completed
self=$$;  ( mysqldump --single-transaction --quick --lock-tables=false -u _0c41c377407f20a5 -p********** _0c41c377407f20a5 -h 127.0.0.1 -P 3306   || kill $self )  | /usr/bin/gzip >> ./arun.com/private/backups/20231120_180003-arun_com-database.sql.gz

Backup Summary for arun.com at 2023-11-20 18:00:04.906139
Config  : ./arun.com/private/backups/20231120_180003-arun_com-site_config_backup.json 94.0B
Database: ./arun.com/private/backups/20231120_180003-arun_com-database.sql.gz         1.1MiB
Backup for Site arun.com has been successfully completed
Backup failed for Site skyai. Database or site_config.json may be corrupted
Traceback (most recent call last):
  File "apps/frappe/frappe/commands/site.py", line 718, in backup
    odb = scheduled_backup(
  File "apps/frappe/frappe/utils/backups.py", line 532, in scheduled_backup
    odb = new_backup(
  File "apps/frappe/frappe/utils/backups.py", line 566, in new_backup
    odb = BackupGenerator(
  File "apps/frappe/frappe/utils/backups.py", line 84, in __init__
    self.setup_backup_tables()
  File "apps/frappe/frappe/utils/backups.py", line 116, in setup_backup_tables
    existing_tables = frappe.db.get_tables()
  File "apps/frappe/frappe/database/mariadb/database.py", line 439, in get_tables
    frappe.qb.from_(information_schema.tables)
  File "apps/frappe/frappe/query_builder/utils.py", line 87, in execute_query
    result = frappe.db.sql(query, params, *args, **kwargs)  # nosemgrep
  File "apps/frappe/frappe/database/database.py", line 201, in sql
    self.connect()
  File "apps/frappe/frappe/database/database.py", line 115, in connect
    self._conn = self.get_connection()
  File "apps/frappe/frappe/database/mariadb/database.py", line 98, in get_connection
    conn = self._get_connection()
  File "apps/frappe/frappe/database/mariadb/database.py", line 104, in _get_connection
    return self.create_connection()
  File "apps/frappe/frappe/database/mariadb/database.py", line 107, in create_connection
    return pymysql.connect(**self.get_connection_settings())
  File "env/lib/python3.10/site-packages/pymysql/connections.py", line 352, in __init__
    self.connect()
  File "env/lib/python3.10/site-packages/pymysql/connections.py", line 636, in connect
    self._request_authentication()
  File "env/lib/python3.10/site-packages/pymysql/connections.py", line 911, in _request_authentication
    auth_packet = self._read_packet()
  File "env/lib/python3.10/site-packages/pymysql/connections.py", line 729, in _read_packet
    packet.raise_for_error()
  File "env/lib/python3.10/site-packages/pymysql/protocol.py", line 221, in raise_for_error
    err.raise_mysql_exception(self._data)
  File "env/lib/python3.10/site-packages/pymysql/err.py", line 143, in raise_mysql_exception
    raise errorclass(errno, errval)
pymysql.err.OperationalError: (1045, "Access denied for user '_a4db896e4fe6001d'@'localhost' (using password: YES)")

Backup failed for Site skyai2. Database or site_config.json may be corrupted
Traceback (most recent call last):
  File "apps/frappe/frappe/commands/site.py", line 718, in backup
    odb = scheduled_backup(
  File "apps/frappe/frappe/utils/backups.py", line 532, in scheduled_backup
    odb = new_backup(
  File "apps/frappe/frappe/utils/backups.py", line 566, in new_backup
    odb = BackupGenerator(
  File "apps/frappe/frappe/utils/backups.py", line 84, in __init__
    self.setup_backup_tables()
  File "apps/frappe/frappe/utils/backups.py", line 116, in setup_backup_tables
    existing_tables = frappe.db.get_tables()
  File "apps/frappe/frappe/database/mariadb/database.py", line 439, in get_tables
    frappe.qb.from_(information_schema.tables)
  File "apps/frappe/frappe/query_builder/utils.py", line 87, in execute_query
    result = frappe.db.sql(query, params, *args, **kwargs)  # nosemgrep
  File "apps/frappe/frappe/database/database.py", line 201, in sql
    self.connect()
  File "apps/frappe/frappe/database/database.py", line 115, in connect
    self._conn = self.get_connection()
  File "apps/frappe/frappe/database/mariadb/database.py", line 98, in get_connection
    conn = self._get_connection()
  File "apps/frappe/frappe/database/mariadb/database.py", line 104, in _get_connection
    return self.create_connection()
  File "apps/frappe/frappe/database/mariadb/database.py", line 107, in create_connection
    return pymysql.connect(**self.get_connection_settings())
  File "env/lib/python3.10/site-packages/pymysql/connections.py", line 352, in __init__
    self.connect()
  File "env/lib/python3.10/site-packages/pymysql/connections.py", line 636, in connect
    self._request_authentication()
  File "env/lib/python3.10/site-packages/pymysql/connections.py", line 911, in _request_authentication
    auth_packet = self._read_packet()
  File "env/lib/python3.10/site-packages/pymysql/connections.py", line 729, in _read_packet
    packet.raise_for_error()
  File "env/lib/python3.10/site-packages/pymysql/protocol.py", line 221, in raise_for_error
    err.raise_mysql_exception(self._data)
  File "env/lib/python3.10/site-packages/pymysql/err.py", line 143, in raise_mysql_exception
    raise errorclass(errno, errval)
pymysql.err.OperationalError: (1045, "Access denied for user '_a4db896e4fe6001d'@'localhost' (using password: YES)")

self=$$;  ( mysqldump --single-transaction --quick --lock-tables=false -u _f3e7bb7e772b3608 -p********** _f3e7bb7e772b3608 -h 127.0.0.1 -P 3306   || kill $self )  | /usr/bin/gzip >> ./arun/private/backups/20231121_120001-arun-database.sql.gz

Backup Summary for arun at 2023-11-21 12:00:03.801701
Config  : ./arun/private/backups/20231121_120001-arun-site_config_backup.json 94.0B
Database: ./arun/private/backups/20231121_120001-arun-database.sql.gz         1.0MiB
Backup for Site arun has been successfully completed
File ./arun.com/private/backups/20231120_180003-arun_com-database.sql.gz is recent
File ./arun.com/private/backups/20231120_180003-arun_com-site_config_backup.json is recent
self=$$;  ( mysqldump --single-transaction --quick --lock-tables=false -u _0c41c377407f20a5 -p********** _0c41c377407f20a5 -h 127.0.0.1 -P 3306   || kill $self )  | /usr/bin/gzip >> ./arun.com/private/backups/20231121_120003-arun_com-database.sql.gz

Backup Summary for arun.com at 2023-11-21 12:00:05.228186
Config  : ./arun.com/private/backups/20231121_120003-arun_com-site_config_backup.json 116.0B
Database: ./arun.com/private/backups/20231121_120003-arun_com-database.sql.gz         1.1MiB
Backup for Site arun.com has been successfully completed
Backup failed for Site skyai. Database or site_config.json may be corrupted
Traceback (most recent call last):
  File "apps/frappe/frappe/commands/site.py", line 718, in backup
    odb = scheduled_backup(
  File "apps/frappe/frappe/utils/backups.py", line 532, in scheduled_backup
    odb = new_backup(
  File "apps/frappe/frappe/utils/backups.py", line 566, in new_backup
    odb = BackupGenerator(
  File "apps/frappe/frappe/utils/backups.py", line 84, in __init__
    self.setup_backup_tables()
  File "apps/frappe/frappe/utils/backups.py", line 116, in setup_backup_tables
    existing_tables = frappe.db.get_tables()
  File "apps/frappe/frappe/database/mariadb/database.py", line 439, in get_tables
    frappe.qb.from_(information_schema.tables)
  File "apps/frappe/frappe/query_builder/utils.py", line 87, in execute_query
    result = frappe.db.sql(query, params, *args, **kwargs)  # nosemgrep
  File "apps/frappe/frappe/database/database.py", line 201, in sql
    self.connect()
  File "apps/frappe/frappe/database/database.py", line 115, in connect
    self._conn = self.get_connection()
  File "apps/frappe/frappe/database/mariadb/database.py", line 98, in get_connection
    conn = self._get_connection()
  File "apps/frappe/frappe/database/mariadb/database.py", line 104, in _get_connection
    return self.create_connection()
  File "apps/frappe/frappe/database/mariadb/database.py", line 107, in create_connection
    return pymysql.connect(**self.get_connection_settings())
  File "env/lib/python3.10/site-packages/pymysql/connections.py", line 352, in __init__
    self.connect()
  File "env/lib/python3.10/site-packages/pymysql/connections.py", line 636, in connect
    self._request_authentication()
  File "env/lib/python3.10/site-packages/pymysql/connections.py", line 911, in _request_authentication
    auth_packet = self._read_packet()
  File "env/lib/python3.10/site-packages/pymysql/connections.py", line 729, in _read_packet
    packet.raise_for_error()
  File "env/lib/python3.10/site-packages/pymysql/protocol.py", line 221, in raise_for_error
    err.raise_mysql_exception(self._data)
  File "env/lib/python3.10/site-packages/pymysql/err.py", line 143, in raise_mysql_exception
    raise errorclass(errno, errval)
pymysql.err.OperationalError: (1045, "Access denied for user '_a4db896e4fe6001d'@'localhost' (using password: YES)")

Backup failed for Site skyai2. Database or site_config.json may be corrupted
Traceback (most recent call last):
  File "apps/frappe/frappe/commands/site.py", line 718, in backup
    odb = scheduled_backup(
  File "apps/frappe/frappe/utils/backups.py", line 532, in scheduled_backup
    odb = new_backup(
  File "apps/frappe/frappe/utils/backups.py", line 566, in new_backup
    odb = BackupGenerator(
  File "apps/frappe/frappe/utils/backups.py", line 84, in __init__
    self.setup_backup_tables()
  File "apps/frappe/frappe/utils/backups.py", line 116, in setup_backup_tables
    existing_tables = frappe.db.get_tables()
  File "apps/frappe/frappe/database/mariadb/database.py", line 439, in get_tables
    frappe.qb.from_(information_schema.tables)
  File "apps/frappe/frappe/query_builder/utils.py", line 87, in execute_query
    result = frappe.db.sql(query, params, *args, **kwargs)  # nosemgrep
  File "apps/frappe/frappe/database/database.py", line 201, in sql
    self.connect()
  File "apps/frappe/frappe/database/database.py", line 115, in connect
    self._conn = self.get_connection()
  File "apps/frappe/frappe/database/mariadb/database.py", line 98, in get_connection
    conn = self._get_connection()
  File "apps/frappe/frappe/database/mariadb/database.py", line 104, in _get_connection
    return self.create_connection()
  File "apps/frappe/frappe/database/mariadb/database.py", line 107, in create_connection
    return pymysql.connect(**self.get_connection_settings())
  File "env/lib/python3.10/site-packages/pymysql/connections.py", line 352, in __init__
    self.connect()
  File "env/lib/python3.10/site-packages/pymysql/connections.py", line 636, in connect
    self._request_authentication()
  File "env/lib/python3.10/site-packages/pymysql/connections.py", line 911, in _request_authentication
    auth_packet = self._read_packet()
  File "env/lib/python3.10/site-packages/pymysql/connections.py", line 729, in _read_packet
    packet.raise_for_error()
  File "env/lib/python3.10/site-packages/pymysql/protocol.py", line 221, in raise_for_error
    err.raise_mysql_exception(self._data)
  File "env/lib/python3.10/site-packages/pymysql/err.py", line 143, in raise_mysql_exception
    raise errorclass(errno, errval)
pymysql.err.OperationalError: (1045, "Access denied for user '_a4db896e4fe6001d'@'localhost' (using password: YES)")

self=$$;  ( mysqldump --single-transaction --quick --lock-tables=false -u _f3e7bb7e772b3608 -p********** _f3e7bb7e772b3608 -h 127.0.0.1 -P 3306   || kill $self )  | /usr/bin/gzip >> ./arun/private/backups/20231121_180002-arun-database.sql.gz

Backup Summary for arun at 2023-11-21 18:00:03.139986
Config  : ./arun/private/backups/20231121_180002-arun-site_config_backup.json 94.0B
Database: ./arun/private/backups/20231121_180002-arun-database.sql.gz         1.0MiB
Backup for Site arun has been successfully completed
File ./arun.com/private/backups/20231120_180003-arun_com-database.sql.gz is recent
File ./arun.com/private/backups/20231121_120003-arun_com-site_config_backup.json is recent
File ./arun.com/private/backups/20231121_120003-arun_com-database.sql.gz is recent
File ./arun.com/private/backups/20231120_180003-arun_com-site_config_backup.json is recent
self=$$;  ( mysqldump --single-transaction --quick --lock-tables=false -u _0c41c377407f20a5 -p********** _0c41c377407f20a5 -h 127.0.0.1 -P 3306   || kill $self )  | /usr/bin/gzip >> ./arun.com/private/backups/20231121_180003-arun_com-database.sql.gz

Backup Summary for arun.com at 2023-11-21 18:00:04.294898
Config  : ./arun.com/private/backups/20231121_180003-arun_com-site_config_backup.json 116.0B
Database: ./arun.com/private/backups/20231121_180003-arun_com-database.sql.gz         1.1MiB
Backup for Site arun.com has been successfully completed
Backup failed for Site skyai. Database or site_config.json may be corrupted
Traceback (most recent call last):
  File "apps/frappe/frappe/commands/site.py", line 718, in backup
    odb = scheduled_backup(
  File "apps/frappe/frappe/utils/backups.py", line 532, in scheduled_backup
    odb = new_backup(
  File "apps/frappe/frappe/utils/backups.py", line 566, in new_backup
    odb = BackupGenerator(
  File "apps/frappe/frappe/utils/backups.py", line 84, in __init__
    self.setup_backup_tables()
  File "apps/frappe/frappe/utils/backups.py", line 116, in setup_backup_tables
    existing_tables = frappe.db.get_tables()
  File "apps/frappe/frappe/database/mariadb/database.py", line 439, in get_tables
    frappe.qb.from_(information_schema.tables)
  File "apps/frappe/frappe/query_builder/utils.py", line 87, in execute_query
    result = frappe.db.sql(query, params, *args, **kwargs)  # nosemgrep
  File "apps/frappe/frappe/database/database.py", line 201, in sql
    self.connect()
  File "apps/frappe/frappe/database/database.py", line 115, in connect
    self._conn = self.get_connection()
  File "apps/frappe/frappe/database/mariadb/database.py", line 98, in get_connection
    conn = self._get_connection()
  File "apps/frappe/frappe/database/mariadb/database.py", line 104, in _get_connection
    return self.create_connection()
  File "apps/frappe/frappe/database/mariadb/database.py", line 107, in create_connection
    return pymysql.connect(**self.get_connection_settings())
  File "env/lib/python3.10/site-packages/pymysql/connections.py", line 352, in __init__
    self.connect()
  File "env/lib/python3.10/site-packages/pymysql/connections.py", line 636, in connect
    self._request_authentication()
  File "env/lib/python3.10/site-packages/pymysql/connections.py", line 911, in _request_authentication
    auth_packet = self._read_packet()
  File "env/lib/python3.10/site-packages/pymysql/connections.py", line 729, in _read_packet
    packet.raise_for_error()
  File "env/lib/python3.10/site-packages/pymysql/protocol.py", line 221, in raise_for_error
    err.raise_mysql_exception(self._data)
  File "env/lib/python3.10/site-packages/pymysql/err.py", line 143, in raise_mysql_exception
    raise errorclass(errno, errval)
pymysql.err.OperationalError: (1045, "Access denied for user '_a4db896e4fe6001d'@'localhost' (using password: YES)")

Backup failed for Site skyai2. Database or site_config.json may be corrupted
Traceback (most recent call last):
  File "apps/frappe/frappe/commands/site.py", line 718, in backup
    odb = scheduled_backup(
  File "apps/frappe/frappe/utils/backups.py", line 532, in scheduled_backup
    odb = new_backup(
  File "apps/frappe/frappe/utils/backups.py", line 566, in new_backup
    odb = BackupGenerator(
  File "apps/frappe/frappe/utils/backups.py", line 84, in __init__
    self.setup_backup_tables()
  File "apps/frappe/frappe/utils/backups.py", line 116, in setup_backup_tables
    existing_tables = frappe.db.get_tables()
  File "apps/frappe/frappe/database/mariadb/database.py", line 439, in get_tables
    frappe.qb.from_(information_schema.tables)
  File "apps/frappe/frappe/query_builder/utils.py", line 87, in execute_query
    result = frappe.db.sql(query, params, *args, **kwargs)  # nosemgrep
  File "apps/frappe/frappe/database/database.py", line 201, in sql
    self.connect()
  File "apps/frappe/frappe/database/database.py", line 115, in connect
    self._conn = self.get_connection()
  File "apps/frappe/frappe/database/mariadb/database.py", line 98, in get_connection
    conn = self._get_connection()
  File "apps/frappe/frappe/database/mariadb/database.py", line 104, in _get_connection
    return self.create_connection()
  File "apps/frappe/frappe/database/mariadb/database.py", line 107, in create_connection
    return pymysql.connect(**self.get_connection_settings())
  File "env/lib/python3.10/site-packages/pymysql/connections.py", line 352, in __init__
    self.connect()
  File "env/lib/python3.10/site-packages/pymysql/connections.py", line 636, in connect
    self._request_authentication()
  File "env/lib/python3.10/site-packages/pymysql/connections.py", line 911, in _request_authentication
    auth_packet = self._read_packet()
  File "env/lib/python3.10/site-packages/pymysql/connections.py", line 729, in _read_packet
    packet.raise_for_error()
  File "env/lib/python3.10/site-packages/pymysql/protocol.py", line 221, in raise_for_error
    err.raise_mysql_exception(self._data)
  File "env/lib/python3.10/site-packages/pymysql/err.py", line 143, in raise_mysql_exception
    raise errorclass(errno, errval)
pymysql.err.OperationalError: (1045, "Access denied for user '_a4db896e4fe6001d'@'localhost' (using password: YES)")

self=$$;  ( mysqldump --single-transaction --quick --lock-tables=false -u _f3e7bb7e772b3608 -p********** _f3e7bb7e772b3608 -h 127.0.0.1 -P 3306   || kill $self )  | /usr/bin/gzip >> ./arun/private/backups/20231122_120001-arun-database.sql.gz

Backup Summary for arun at 2023-11-22 12:00:03.287607
Config  : ./arun/private/backups/20231122_120001-arun-site_config_backup.json 94.0B
Database: ./arun/private/backups/20231122_120001-arun-database.sql.gz         1.0MiB
Backup for Site arun has been successfully completed
File ./arun.com/private/backups/20231121_180003-arun_com-site_config_backup.json is recent
File ./arun.com/private/backups/20231120_180003-arun_com-database.sql.gz is older than 24 hours
File ./arun.com/private/backups/20231121_120003-arun_com-site_config_backup.json is recent
File ./arun.com/private/backups/20231121_120003-arun_com-database.sql.gz is recent
File ./arun.com/private/backups/20231121_180003-arun_com-database.sql.gz is recent
File ./arun.com/private/backups/20231120_180003-arun_com-site_config_backup.json is older than 24 hours
self=$$;  ( mysqldump --single-transaction --quick --lock-tables=false -u _0c41c377407f20a5 -p********** _0c41c377407f20a5 -h 127.0.0.1 -P 3306   || kill $self )  | /usr/bin/gzip >> ./arun.com/private/backups/20231122_120003-arun_com-database.sql.gz

Backup Summary for arun.com at 2023-11-22 12:00:04.447686
Config  : ./arun.com/private/backups/20231122_120003-arun_com-site_config_backup.json 116.0B
Database: ./arun.com/private/backups/20231122_120003-arun_com-database.sql.gz         1.1MiB
Backup for Site arun.com has been successfully completed
Backup failed for Site skyai. Database or site_config.json may be corrupted
Traceback (most recent call last):
  File "apps/frappe/frappe/commands/site.py", line 718, in backup
    odb = scheduled_backup(
  File "apps/frappe/frappe/utils/backups.py", line 532, in scheduled_backup
    odb = new_backup(
  File "apps/frappe/frappe/utils/backups.py", line 566, in new_backup
    odb = BackupGenerator(
  File "apps/frappe/frappe/utils/backups.py", line 84, in __init__
    self.setup_backup_tables()
  File "apps/frappe/frappe/utils/backups.py", line 116, in setup_backup_tables
    existing_tables = frappe.db.get_tables()
  File "apps/frappe/frappe/database/mariadb/database.py", line 439, in get_tables
    frappe.qb.from_(information_schema.tables)
  File "apps/frappe/frappe/query_builder/utils.py", line 87, in execute_query
    result = frappe.db.sql(query, params, *args, **kwargs)  # nosemgrep
  File "apps/frappe/frappe/database/database.py", line 201, in sql
    self.connect()
  File "apps/frappe/frappe/database/database.py", line 115, in connect
    self._conn = self.get_connection()
  File "apps/frappe/frappe/database/mariadb/database.py", line 98, in get_connection
    conn = self._get_connection()
  File "apps/frappe/frappe/database/mariadb/database.py", line 104, in _get_connection
    return self.create_connection()
  File "apps/frappe/frappe/database/mariadb/database.py", line 107, in create_connection
    return pymysql.connect(**self.get_connection_settings())
  File "env/lib/python3.10/site-packages/pymysql/connections.py", line 352, in __init__
    self.connect()
  File "env/lib/python3.10/site-packages/pymysql/connections.py", line 636, in connect
    self._request_authentication()
  File "env/lib/python3.10/site-packages/pymysql/connections.py", line 911, in _request_authentication
    auth_packet = self._read_packet()
  File "env/lib/python3.10/site-packages/pymysql/connections.py", line 729, in _read_packet
    packet.raise_for_error()
  File "env/lib/python3.10/site-packages/pymysql/protocol.py", line 221, in raise_for_error
    err.raise_mysql_exception(self._data)
  File "env/lib/python3.10/site-packages/pymysql/err.py", line 143, in raise_mysql_exception
    raise errorclass(errno, errval)
pymysql.err.OperationalError: (1045, "Access denied for user '_a4db896e4fe6001d'@'localhost' (using password: YES)")

Backup failed for Site skyai2. Database or site_config.json may be corrupted
Traceback (most recent call last):
  File "apps/frappe/frappe/commands/site.py", line 718, in backup
    odb = scheduled_backup(
  File "apps/frappe/frappe/utils/backups.py", line 532, in scheduled_backup
    odb = new_backup(
  File "apps/frappe/frappe/utils/backups.py", line 566, in new_backup
    odb = BackupGenerator(
  File "apps/frappe/frappe/utils/backups.py", line 84, in __init__
    self.setup_backup_tables()
  File "apps/frappe/frappe/utils/backups.py", line 116, in setup_backup_tables
    existing_tables = frappe.db.get_tables()
  File "apps/frappe/frappe/database/mariadb/database.py", line 439, in get_tables
    frappe.qb.from_(information_schema.tables)
  File "apps/frappe/frappe/query_builder/utils.py", line 87, in execute_query
    result = frappe.db.sql(query, params, *args, **kwargs)  # nosemgrep
  File "apps/frappe/frappe/database/database.py", line 201, in sql
    self.connect()
  File "apps/frappe/frappe/database/database.py", line 115, in connect
    self._conn = self.get_connection()
  File "apps/frappe/frappe/database/mariadb/database.py", line 98, in get_connection
    conn = self._get_connection()
  File "apps/frappe/frappe/database/mariadb/database.py", line 104, in _get_connection
    return self.create_connection()
  File "apps/frappe/frappe/database/mariadb/database.py", line 107, in create_connection
    return pymysql.connect(**self.get_connection_settings())
  File "env/lib/python3.10/site-packages/pymysql/connections.py", line 352, in __init__
    self.connect()
  File "env/lib/python3.10/site-packages/pymysql/connections.py", line 636, in connect
    self._request_authentication()
  File "env/lib/python3.10/site-packages/pymysql/connections.py", line 911, in _request_authentication
    auth_packet = self._read_packet()
  File "env/lib/python3.10/site-packages/pymysql/connections.py", line 729, in _read_packet
    packet.raise_for_error()
  File "env/lib/python3.10/site-packages/pymysql/protocol.py", line 221, in raise_for_error
    err.raise_mysql_exception(self._data)
  File "env/lib/python3.10/site-packages/pymysql/err.py", line 143, in raise_mysql_exception
    raise errorclass(errno, errval)
pymysql.err.OperationalError: (1045, "Access denied for user '_a4db896e4fe6001d'@'localhost' (using password: YES)")

self=$$;  ( mysqldump --single-transaction --quick --lock-tables=false -u _f3e7bb7e772b3608 -p********** _f3e7bb7e772b3608 -h 127.0.0.1 -P 3306   || kill $self )  | /usr/bin/gzip >> ./arun/private/backups/20231122_180001-arun-database.sql.gz

Backup Summary for arun at 2023-11-22 18:00:02.696836
Config  : ./arun/private/backups/20231122_180001-arun-site_config_backup.json 94.0B
Database: ./arun/private/backups/20231122_180001-arun-database.sql.gz         1.0MiB
Backup for Site arun has been successfully completed
File ./arun.com/private/backups/20231121_180003-arun_com-site_config_backup.json is recent
File ./arun.com/private/backups/20231122_120003-arun_com-site_config_backup.json is recent
File ./arun.com/private/backups/20231121_120003-arun_com-site_config_backup.json is older than 24 hours
File ./arun.com/private/backups/20231121_120003-arun_com-database.sql.gz is older than 24 hours
File ./arun.com/private/backups/20231121_180003-arun_com-database.sql.gz is recent
File ./arun.com/private/backups/20231122_120003-arun_com-database.sql.gz is recent
self=$$;  ( mysqldump --single-transaction --quick --lock-tables=false -u _0c41c377407f20a5 -p********** _0c41c377407f20a5 -h 127.0.0.1 -P 3306   || kill $self )  | /usr/bin/gzip >> ./arun.com/private/backups/20231122_180002-arun_com-database.sql.gz

Backup Summary for arun.com at 2023-11-22 18:00:03.842749
Config  : ./arun.com/private/backups/20231122_180002-arun_com-site_config_backup.json 116.0B
Database: ./arun.com/private/backups/20231122_180002-arun_com-database.sql.gz         1.2MiB
Backup for Site arun.com has been successfully completed
Backup failed for Site skyai. Database or site_config.json may be corrupted
Traceback (most recent call last):
  File "apps/frappe/frappe/commands/site.py", line 718, in backup
    odb = scheduled_backup(
  File "apps/frappe/frappe/utils/backups.py", line 532, in scheduled_backup
    odb = new_backup(
  File "apps/frappe/frappe/utils/backups.py", line 566, in new_backup
    odb = BackupGenerator(
  File "apps/frappe/frappe/utils/backups.py", line 84, in __init__
    self.setup_backup_tables()
  File "apps/frappe/frappe/utils/backups.py", line 116, in setup_backup_tables
    existing_tables = frappe.db.get_tables()
  File "apps/frappe/frappe/database/mariadb/database.py", line 439, in get_tables
    frappe.qb.from_(information_schema.tables)
  File "apps/frappe/frappe/query_builder/utils.py", line 87, in execute_query
    result = frappe.db.sql(query, params, *args, **kwargs)  # nosemgrep
  File "apps/frappe/frappe/database/database.py", line 201, in sql
    self.connect()
  File "apps/frappe/frappe/database/database.py", line 115, in connect
    self._conn = self.get_connection()
  File "apps/frappe/frappe/database/mariadb/database.py", line 98, in get_connection
    conn = self._get_connection()
  File "apps/frappe/frappe/database/mariadb/database.py", line 104, in _get_connection
    return self.create_connection()
  File "apps/frappe/frappe/database/mariadb/database.py", line 107, in create_connection
    return pymysql.connect(**self.get_connection_settings())
  File "env/lib/python3.10/site-packages/pymysql/connections.py", line 352, in __init__
    self.connect()
  File "env/lib/python3.10/site-packages/pymysql/connections.py", line 636, in connect
    self._request_authentication()
  File "env/lib/python3.10/site-packages/pymysql/connections.py", line 911, in _request_authentication
    auth_packet = self._read_packet()
  File "env/lib/python3.10/site-packages/pymysql/connections.py", line 729, in _read_packet
    packet.raise_for_error()
  File "env/lib/python3.10/site-packages/pymysql/protocol.py", line 221, in raise_for_error
    err.raise_mysql_exception(self._data)
  File "env/lib/python3.10/site-packages/pymysql/err.py", line 143, in raise_mysql_exception
    raise errorclass(errno, errval)
pymysql.err.OperationalError: (1045, "Access denied for user '_a4db896e4fe6001d'@'localhost' (using password: YES)")

Backup failed for Site skyai2. Database or site_config.json may be corrupted
Traceback (most recent call last):
  File "apps/frappe/frappe/commands/site.py", line 718, in backup
    odb = scheduled_backup(
  File "apps/frappe/frappe/utils/backups.py", line 532, in scheduled_backup
    odb = new_backup(
  File "apps/frappe/frappe/utils/backups.py", line 566, in new_backup
    odb = BackupGenerator(
  File "apps/frappe/frappe/utils/backups.py", line 84, in __init__
    self.setup_backup_tables()
  File "apps/frappe/frappe/utils/backups.py", line 116, in setup_backup_tables
    existing_tables = frappe.db.get_tables()
  File "apps/frappe/frappe/database/mariadb/database.py", line 439, in get_tables
    frappe.qb.from_(information_schema.tables)
  File "apps/frappe/frappe/query_builder/utils.py", line 87, in execute_query
    result = frappe.db.sql(query, params, *args, **kwargs)  # nosemgrep
  File "apps/frappe/frappe/database/database.py", line 201, in sql
    self.connect()
  File "apps/frappe/frappe/database/database.py", line 115, in connect
    self._conn = self.get_connection()
  File "apps/frappe/frappe/database/mariadb/database.py", line 98, in get_connection
    conn = self._get_connection()
  File "apps/frappe/frappe/database/mariadb/database.py", line 104, in _get_connection
    return self.create_connection()
  File "apps/frappe/frappe/database/mariadb/database.py", line 107, in create_connection
    return pymysql.connect(**self.get_connection_settings())
  File "env/lib/python3.10/site-packages/pymysql/connections.py", line 352, in __init__
    self.connect()
  File "env/lib/python3.10/site-packages/pymysql/connections.py", line 636, in connect
    self._request_authentication()
  File "env/lib/python3.10/site-packages/pymysql/connections.py", line 911, in _request_authentication
    auth_packet = self._read_packet()
  File "env/lib/python3.10/site-packages/pymysql/connections.py", line 729, in _read_packet
    packet.raise_for_error()
  File "env/lib/python3.10/site-packages/pymysql/protocol.py", line 221, in raise_for_error
    err.raise_mysql_exception(self._data)
  File "env/lib/python3.10/site-packages/pymysql/err.py", line 143, in raise_mysql_exception
    raise errorclass(errno, errval)
pymysql.err.OperationalError: (1045, "Access denied for user '_a4db896e4fe6001d'@'localhost' (using password: YES)")

self=$$;  ( mysqldump --single-transaction --quick --lock-tables=false -u _f3e7bb7e772b3608 -p********** _f3e7bb7e772b3608 -h 127.0.0.1 -P 3306   || kill $self )  | /usr/bin/gzip >> ./arun/private/backups/20231123_120001-arun-database.sql.gz

Backup Summary for arun at 2023-11-23 12:00:03.867732
Config  : ./arun/private/backups/20231123_120001-arun-site_config_backup.json 94.0B
Database: ./arun/private/backups/20231123_120001-arun-database.sql.gz         1.0MiB
Backup for Site arun has been successfully completed
File ./arun.com/private/backups/20231122_180002-arun_com-database.sql.gz is recent
File ./arun.com/private/backups/20231121_180003-arun_com-site_config_backup.json is older than 24 hours
File ./arun.com/private/backups/20231122_180002-arun_com-site_config_backup.json is recent
File ./arun.com/private/backups/20231122_120003-arun_com-site_config_backup.json is recent
File ./arun.com/private/backups/20231121_180003-arun_com-database.sql.gz is older than 24 hours
File ./arun.com/private/backups/20231122_120003-arun_com-database.sql.gz is recent
self=$$;  ( mysqldump --single-transaction --quick --lock-tables=false -u _0c41c377407f20a5 -p********** _0c41c377407f20a5 -h 127.0.0.1 -P 3306   || kill $self )  | /usr/bin/gzip >> ./arun.com/private/backups/20231123_120003-arun_com-database.sql.gz

Backup Summary for arun.com at 2023-11-23 12:00:05.036910
Config  : ./arun.com/private/backups/20231123_120003-arun_com-site_config_backup.json 116.0B
Database: ./arun.com/private/backups/20231123_120003-arun_com-database.sql.gz         1.2MiB
Backup for Site arun.com has been successfully completed
Backup failed for Site skyai. Database or site_config.json may be corrupted
Traceback (most recent call last):
  File "apps/frappe/frappe/commands/site.py", line 718, in backup
    odb = scheduled_backup(
  File "apps/frappe/frappe/utils/backups.py", line 532, in scheduled_backup
    odb = new_backup(
  File "apps/frappe/frappe/utils/backups.py", line 566, in new_backup
    odb = BackupGenerator(
  File "apps/frappe/frappe/utils/backups.py", line 84, in __init__
    self.setup_backup_tables()
  File "apps/frappe/frappe/utils/backups.py", line 116, in setup_backup_tables
    existing_tables = frappe.db.get_tables()
  File "apps/frappe/frappe/database/mariadb/database.py", line 439, in get_tables
    frappe.qb.from_(information_schema.tables)
  File "apps/frappe/frappe/query_builder/utils.py", line 87, in execute_query
    result = frappe.db.sql(query, params, *args, **kwargs)  # nosemgrep
  File "apps/frappe/frappe/database/database.py", line 201, in sql
    self.connect()
  File "apps/frappe/frappe/database/database.py", line 115, in connect
    self._conn = self.get_connection()
  File "apps/frappe/frappe/database/mariadb/database.py", line 98, in get_connection
    conn = self._get_connection()
  File "apps/frappe/frappe/database/mariadb/database.py", line 104, in _get_connection
    return self.create_connection()
  File "apps/frappe/frappe/database/mariadb/database.py", line 107, in create_connection
    return pymysql.connect(**self.get_connection_settings())
  File "env/lib/python3.10/site-packages/pymysql/connections.py", line 352, in __init__
    self.connect()
  File "env/lib/python3.10/site-packages/pymysql/connections.py", line 636, in connect
    self._request_authentication()
  File "env/lib/python3.10/site-packages/pymysql/connections.py", line 911, in _request_authentication
    auth_packet = self._read_packet()
  File "env/lib/python3.10/site-packages/pymysql/connections.py", line 729, in _read_packet
    packet.raise_for_error()
  File "env/lib/python3.10/site-packages/pymysql/protocol.py", line 221, in raise_for_error
    err.raise_mysql_exception(self._data)
  File "env/lib/python3.10/site-packages/pymysql/err.py", line 143, in raise_mysql_exception
    raise errorclass(errno, errval)
pymysql.err.OperationalError: (1045, "Access denied for user '_a4db896e4fe6001d'@'localhost' (using password: YES)")

Backup failed for Site skyai2. Database or site_config.json may be corrupted
Traceback (most recent call last):
  File "apps/frappe/frappe/commands/site.py", line 718, in backup
    odb = scheduled_backup(
  File "apps/frappe/frappe/utils/backups.py", line 532, in scheduled_backup
    odb = new_backup(
  File "apps/frappe/frappe/utils/backups.py", line 566, in new_backup
    odb = BackupGenerator(
  File "apps/frappe/frappe/utils/backups.py", line 84, in __init__
    self.setup_backup_tables()
  File "apps/frappe/frappe/utils/backups.py", line 116, in setup_backup_tables
    existing_tables = frappe.db.get_tables()
  File "apps/frappe/frappe/database/mariadb/database.py", line 439, in get_tables
    frappe.qb.from_(information_schema.tables)
  File "apps/frappe/frappe/query_builder/utils.py", line 87, in execute_query
    result = frappe.db.sql(query, params, *args, **kwargs)  # nosemgrep
  File "apps/frappe/frappe/database/database.py", line 201, in sql
    self.connect()
  File "apps/frappe/frappe/database/database.py", line 115, in connect
    self._conn = self.get_connection()
  File "apps/frappe/frappe/database/mariadb/database.py", line 98, in get_connection
    conn = self._get_connection()
  File "apps/frappe/frappe/database/mariadb/database.py", line 104, in _get_connection
    return self.create_connection()
  File "apps/frappe/frappe/database/mariadb/database.py", line 107, in create_connection
    return pymysql.connect(**self.get_connection_settings())
  File "env/lib/python3.10/site-packages/pymysql/connections.py", line 352, in __init__
    self.connect()
  File "env/lib/python3.10/site-packages/pymysql/connections.py", line 636, in connect
    self._request_authentication()
  File "env/lib/python3.10/site-packages/pymysql/connections.py", line 911, in _request_authentication
    auth_packet = self._read_packet()
  File "env/lib/python3.10/site-packages/pymysql/connections.py", line 729, in _read_packet
    packet.raise_for_error()
  File "env/lib/python3.10/site-packages/pymysql/protocol.py", line 221, in raise_for_error
    err.raise_mysql_exception(self._data)
  File "env/lib/python3.10/site-packages/pymysql/err.py", line 143, in raise_mysql_exception
    raise errorclass(errno, errval)
pymysql.err.OperationalError: (1045, "Access denied for user '_a4db896e4fe6001d'@'localhost' (using password: YES)")

self=$$;  ( mysqldump --single-transaction --quick --lock-tables=false -u _f3e7bb7e772b3608 -p********** _f3e7bb7e772b3608 -h 127.0.0.1 -P 3306   || kill $self )  | /usr/bin/gzip >> ./arun/private/backups/20231123_180002-arun-database.sql.gz

Backup Summary for arun at 2023-11-23 18:00:03.738414
Config  : ./arun/private/backups/20231123_180002-arun-site_config_backup.json 94.0B
Database: ./arun/private/backups/20231123_180002-arun-database.sql.gz         1.0MiB
Backup for Site arun has been successfully completed
File ./arun.com/private/backups/20231122_180002-arun_com-database.sql.gz is recent
File ./arun.com/private/backups/20231123_120003-arun_com-site_config_backup.json is recent
File ./arun.com/private/backups/20231122_180002-arun_com-site_config_backup.json is recent
File ./arun.com/private/backups/20231122_120003-arun_com-site_config_backup.json is older than 24 hours
File ./arun.com/private/backups/20231123_120003-arun_com-database.sql.gz is recent
File ./arun.com/private/backups/20231122_120003-arun_com-database.sql.gz is older than 24 hours
self=$$;  ( mysqldump --single-transaction --quick --lock-tables=false -u _0c41c377407f20a5 -p********** _0c41c377407f20a5 -h 127.0.0.1 -P 3306   || kill $self )  | /usr/bin/gzip >> ./arun.com/private/backups/20231123_180003-arun_com-database.sql.gz

Backup Summary for arun.com at 2023-11-23 18:00:04.918362
Config  : ./arun.com/private/backups/20231123_180003-arun_com-site_config_backup.json 116.0B
Database: ./arun.com/private/backups/20231123_180003-arun_com-database.sql.gz         1.2MiB
Backup for Site arun.com has been successfully completed
Backup failed for Site skyai. Database or site_config.json may be corrupted
Traceback (most recent call last):
  File "apps/frappe/frappe/commands/site.py", line 718, in backup
    odb = scheduled_backup(
  File "apps/frappe/frappe/utils/backups.py", line 532, in scheduled_backup
    odb = new_backup(
  File "apps/frappe/frappe/utils/backups.py", line 566, in new_backup
    odb = BackupGenerator(
  File "apps/frappe/frappe/utils/backups.py", line 84, in __init__
    self.setup_backup_tables()
  File "apps/frappe/frappe/utils/backups.py", line 116, in setup_backup_tables
    existing_tables = frappe.db.get_tables()
  File "apps/frappe/frappe/database/mariadb/database.py", line 439, in get_tables
    frappe.qb.from_(information_schema.tables)
  File "apps/frappe/frappe/query_builder/utils.py", line 87, in execute_query
    result = frappe.db.sql(query, params, *args, **kwargs)  # nosemgrep
  File "apps/frappe/frappe/database/database.py", line 201, in sql
    self.connect()
  File "apps/frappe/frappe/database/database.py", line 115, in connect
    self._conn = self.get_connection()
  File "apps/frappe/frappe/database/mariadb/database.py", line 98, in get_connection
    conn = self._get_connection()
  File "apps/frappe/frappe/database/mariadb/database.py", line 104, in _get_connection
    return self.create_connection()
  File "apps/frappe/frappe/database/mariadb/database.py", line 107, in create_connection
    return pymysql.connect(**self.get_connection_settings())
  File "env/lib/python3.10/site-packages/pymysql/connections.py", line 352, in __init__
    self.connect()
  File "env/lib/python3.10/site-packages/pymysql/connections.py", line 636, in connect
    self._request_authentication()
  File "env/lib/python3.10/site-packages/pymysql/connections.py", line 911, in _request_authentication
    auth_packet = self._read_packet()
  File "env/lib/python3.10/site-packages/pymysql/connections.py", line 729, in _read_packet
    packet.raise_for_error()
  File "env/lib/python3.10/site-packages/pymysql/protocol.py", line 221, in raise_for_error
    err.raise_mysql_exception(self._data)
  File "env/lib/python3.10/site-packages/pymysql/err.py", line 143, in raise_mysql_exception
    raise errorclass(errno, errval)
pymysql.err.OperationalError: (1045, "Access denied for user '_a4db896e4fe6001d'@'localhost' (using password: YES)")

Backup failed for Site skyai2. Database or site_config.json may be corrupted
Traceback (most recent call last):
  File "apps/frappe/frappe/commands/site.py", line 718, in backup
    odb = scheduled_backup(
  File "apps/frappe/frappe/utils/backups.py", line 532, in scheduled_backup
    odb = new_backup(
  File "apps/frappe/frappe/utils/backups.py", line 566, in new_backup
    odb = BackupGenerator(
  File "apps/frappe/frappe/utils/backups.py", line 84, in __init__
    self.setup_backup_tables()
  File "apps/frappe/frappe/utils/backups.py", line 116, in setup_backup_tables
    existing_tables = frappe.db.get_tables()
  File "apps/frappe/frappe/database/mariadb/database.py", line 439, in get_tables
    frappe.qb.from_(information_schema.tables)
  File "apps/frappe/frappe/query_builder/utils.py", line 87, in execute_query
    result = frappe.db.sql(query, params, *args, **kwargs)  # nosemgrep
  File "apps/frappe/frappe/database/database.py", line 201, in sql
    self.connect()
  File "apps/frappe/frappe/database/database.py", line 115, in connect
    self._conn = self.get_connection()
  File "apps/frappe/frappe/database/mariadb/database.py", line 98, in get_connection
    conn = self._get_connection()
  File "apps/frappe/frappe/database/mariadb/database.py", line 104, in _get_connection
    return self.create_connection()
  File "apps/frappe/frappe/database/mariadb/database.py", line 107, in create_connection
    return pymysql.connect(**self.get_connection_settings())
  File "env/lib/python3.10/site-packages/pymysql/connections.py", line 352, in __init__
    self.connect()
  File "env/lib/python3.10/site-packages/pymysql/connections.py", line 636, in connect
    self._request_authentication()
  File "env/lib/python3.10/site-packages/pymysql/connections.py", line 911, in _request_authentication
    auth_packet = self._read_packet()
  File "env/lib/python3.10/site-packages/pymysql/connections.py", line 729, in _read_packet
    packet.raise_for_error()
  File "env/lib/python3.10/site-packages/pymysql/protocol.py", line 221, in raise_for_error
    err.raise_mysql_exception(self._data)
  File "env/lib/python3.10/site-packages/pymysql/err.py", line 143, in raise_mysql_exception
    raise errorclass(errno, errval)
pymysql.err.OperationalError: (1045, "Access denied for user '_a4db896e4fe6001d'@'localhost' (using password: YES)")

self=$$;  ( mysqldump --single-transaction --quick --lock-tables=false -u _f3e7bb7e772b3608 -p********** _f3e7bb7e772b3608 -h 127.0.0.1 -P 3306   || kill $self )  | /usr/bin/gzip >> ./arun/private/backups/20231124_120002-arun-database.sql.gz

Backup Summary for arun at 2023-11-24 12:00:04.404834
Config  : ./arun/private/backups/20231124_120002-arun-site_config_backup.json 94.0B
Database: ./arun/private/backups/20231124_120002-arun-database.sql.gz         1.0MiB
Backup for Site arun has been successfully completed
File ./arun.com/private/backups/20231122_180002-arun_com-database.sql.gz is older than 24 hours
File ./arun.com/private/backups/20231123_120003-arun_com-site_config_backup.json is recent
File ./arun.com/private/backups/20231122_180002-arun_com-site_config_backup.json is older than 24 hours
File ./arun.com/private/backups/20231123_180003-arun_com-site_config_backup.json is recent
File ./arun.com/private/backups/20231123_120003-arun_com-database.sql.gz is recent
File ./arun.com/private/backups/20231123_180003-arun_com-database.sql.gz is recent
self=$$;  ( mysqldump --single-transaction --quick --lock-tables=false -u _0c41c377407f20a5 -p********** _0c41c377407f20a5 -h 127.0.0.1 -P 3306   || kill $self )  | /usr/bin/gzip >> ./arun.com/private/backups/20231124_120004-arun_com-database.sql.gz

Backup Summary for arun.com at 2023-11-24 12:00:05.625605
Config  : ./arun.com/private/backups/20231124_120004-arun_com-site_config_backup.json 183.0B
Database: ./arun.com/private/backups/20231124_120004-arun_com-database.sql.gz         1.2MiB
Backup for Site arun.com has been successfully completed
Backup failed for Site skyai. Database or site_config.json may be corrupted
Traceback (most recent call last):
  File "apps/frappe/frappe/commands/site.py", line 718, in backup
    odb = scheduled_backup(
  File "apps/frappe/frappe/utils/backups.py", line 532, in scheduled_backup
    odb = new_backup(
  File "apps/frappe/frappe/utils/backups.py", line 566, in new_backup
    odb = BackupGenerator(
  File "apps/frappe/frappe/utils/backups.py", line 84, in __init__
    self.setup_backup_tables()
  File "apps/frappe/frappe/utils/backups.py", line 116, in setup_backup_tables
    existing_tables = frappe.db.get_tables()
  File "apps/frappe/frappe/database/mariadb/database.py", line 439, in get_tables
    frappe.qb.from_(information_schema.tables)
  File "apps/frappe/frappe/query_builder/utils.py", line 87, in execute_query
    result = frappe.db.sql(query, params, *args, **kwargs)  # nosemgrep
  File "apps/frappe/frappe/database/database.py", line 201, in sql
    self.connect()
  File "apps/frappe/frappe/database/database.py", line 115, in connect
    self._conn = self.get_connection()
  File "apps/frappe/frappe/database/mariadb/database.py", line 98, in get_connection
    conn = self._get_connection()
  File "apps/frappe/frappe/database/mariadb/database.py", line 104, in _get_connection
    return self.create_connection()
  File "apps/frappe/frappe/database/mariadb/database.py", line 107, in create_connection
    return pymysql.connect(**self.get_connection_settings())
  File "env/lib/python3.10/site-packages/pymysql/connections.py", line 352, in __init__
    self.connect()
  File "env/lib/python3.10/site-packages/pymysql/connections.py", line 636, in connect
    self._request_authentication()
  File "env/lib/python3.10/site-packages/pymysql/connections.py", line 911, in _request_authentication
    auth_packet = self._read_packet()
  File "env/lib/python3.10/site-packages/pymysql/connections.py", line 729, in _read_packet
    packet.raise_for_error()
  File "env/lib/python3.10/site-packages/pymysql/protocol.py", line 221, in raise_for_error
    err.raise_mysql_exception(self._data)
  File "env/lib/python3.10/site-packages/pymysql/err.py", line 143, in raise_mysql_exception
    raise errorclass(errno, errval)
pymysql.err.OperationalError: (1045, "Access denied for user '_a4db896e4fe6001d'@'localhost' (using password: YES)")

Backup failed for Site skyai2. Database or site_config.json may be corrupted
Traceback (most recent call last):
  File "apps/frappe/frappe/commands/site.py", line 718, in backup
    odb = scheduled_backup(
  File "apps/frappe/frappe/utils/backups.py", line 532, in scheduled_backup
    odb = new_backup(
  File "apps/frappe/frappe/utils/backups.py", line 566, in new_backup
    odb = BackupGenerator(
  File "apps/frappe/frappe/utils/backups.py", line 84, in __init__
    self.setup_backup_tables()
  File "apps/frappe/frappe/utils/backups.py", line 116, in setup_backup_tables
    existing_tables = frappe.db.get_tables()
  File "apps/frappe/frappe/database/mariadb/database.py", line 439, in get_tables
    frappe.qb.from_(information_schema.tables)
  File "apps/frappe/frappe/query_builder/utils.py", line 87, in execute_query
    result = frappe.db.sql(query, params, *args, **kwargs)  # nosemgrep
  File "apps/frappe/frappe/database/database.py", line 201, in sql
    self.connect()
  File "apps/frappe/frappe/database/database.py", line 115, in connect
    self._conn = self.get_connection()
  File "apps/frappe/frappe/database/mariadb/database.py", line 98, in get_connection
    conn = self._get_connection()
  File "apps/frappe/frappe/database/mariadb/database.py", line 104, in _get_connection
    return self.create_connection()
  File "apps/frappe/frappe/database/mariadb/database.py", line 107, in create_connection
    return pymysql.connect(**self.get_connection_settings())
  File "env/lib/python3.10/site-packages/pymysql/connections.py", line 352, in __init__
    self.connect()
  File "env/lib/python3.10/site-packages/pymysql/connections.py", line 636, in connect
    self._request_authentication()
  File "env/lib/python3.10/site-packages/pymysql/connections.py", line 911, in _request_authentication
    auth_packet = self._read_packet()
  File "env/lib/python3.10/site-packages/pymysql/connections.py", line 729, in _read_packet
    packet.raise_for_error()
  File "env/lib/python3.10/site-packages/pymysql/protocol.py", line 221, in raise_for_error
    err.raise_mysql_exception(self._data)
  File "env/lib/python3.10/site-packages/pymysql/err.py", line 143, in raise_mysql_exception
    raise errorclass(errno, errval)
pymysql.err.OperationalError: (1045, "Access denied for user '_a4db896e4fe6001d'@'localhost' (using password: YES)")

self=$$;  ( mysqldump --single-transaction --quick --lock-tables=false -u _f3e7bb7e772b3608 -p********** _f3e7bb7e772b3608 -h 127.0.0.1 -P 3306   || kill $self )  | /usr/bin/gzip >> ./arun/private/backups/20231124_180002-arun-database.sql.gz

Backup Summary for arun at 2023-11-24 18:00:04.395412
Config  : ./arun/private/backups/20231124_180002-arun-site_config_backup.json 94.0B
Database: ./arun/private/backups/20231124_180002-arun-database.sql.gz         1.0MiB
Backup for Site arun has been successfully completed
File ./arun.com/private/backups/20231123_120003-arun_com-site_config_backup.json is older than 24 hours
File ./arun.com/private/backups/20231124_120004-arun_com-database.sql.gz is recent
File ./arun.com/private/backups/20231123_180003-arun_com-site_config_backup.json is recent
File ./arun.com/private/backups/20231123_120003-arun_com-database.sql.gz is older than 24 hours
File ./arun.com/private/backups/20231124_120004-arun_com-site_config_backup.json is recent
File ./arun.com/private/backups/20231123_180003-arun_com-database.sql.gz is recent
self=$$;  ( mysqldump --single-transaction --quick --lock-tables=false -u _0c41c377407f20a5 -p********** _0c41c377407f20a5 -h 127.0.0.1 -P 3306   || kill $self )  | /usr/bin/gzip >> ./arun.com/private/backups/20231124_180004-arun_com-database.sql.gz

Backup Summary for arun.com at 2023-11-24 18:00:05.848394
Config  : ./arun.com/private/backups/20231124_180004-arun_com-site_config_backup.json 183.0B
Database: ./arun.com/private/backups/20231124_180004-arun_com-database.sql.gz         1.2MiB
Backup for Site arun.com has been successfully completed
Backup failed for Site skyai. Database or site_config.json may be corrupted
Traceback (most recent call last):
  File "apps/frappe/frappe/commands/site.py", line 718, in backup
    odb = scheduled_backup(
  File "apps/frappe/frappe/utils/backups.py", line 532, in scheduled_backup
    odb = new_backup(
  File "apps/frappe/frappe/utils/backups.py", line 566, in new_backup
    odb = BackupGenerator(
  File "apps/frappe/frappe/utils/backups.py", line 84, in __init__
    self.setup_backup_tables()
  File "apps/frappe/frappe/utils/backups.py", line 116, in setup_backup_tables
    existing_tables = frappe.db.get_tables()
  File "apps/frappe/frappe/database/mariadb/database.py", line 439, in get_tables
    frappe.qb.from_(information_schema.tables)
  File "apps/frappe/frappe/query_builder/utils.py", line 87, in execute_query
    result = frappe.db.sql(query, params, *args, **kwargs)  # nosemgrep
  File "apps/frappe/frappe/database/database.py", line 201, in sql
    self.connect()
  File "apps/frappe/frappe/database/database.py", line 115, in connect
    self._conn = self.get_connection()
  File "apps/frappe/frappe/database/mariadb/database.py", line 98, in get_connection
    conn = self._get_connection()
  File "apps/frappe/frappe/database/mariadb/database.py", line 104, in _get_connection
    return self.create_connection()
  File "apps/frappe/frappe/database/mariadb/database.py", line 107, in create_connection
    return pymysql.connect(**self.get_connection_settings())
  File "env/lib/python3.10/site-packages/pymysql/connections.py", line 352, in __init__
    self.connect()
  File "env/lib/python3.10/site-packages/pymysql/connections.py", line 636, in connect
    self._request_authentication()
  File "env/lib/python3.10/site-packages/pymysql/connections.py", line 911, in _request_authentication
    auth_packet = self._read_packet()
  File "env/lib/python3.10/site-packages/pymysql/connections.py", line 729, in _read_packet
    packet.raise_for_error()
  File "env/lib/python3.10/site-packages/pymysql/protocol.py", line 221, in raise_for_error
    err.raise_mysql_exception(self._data)
  File "env/lib/python3.10/site-packages/pymysql/err.py", line 143, in raise_mysql_exception
    raise errorclass(errno, errval)
pymysql.err.OperationalError: (1045, "Access denied for user '_a4db896e4fe6001d'@'localhost' (using password: YES)")

Backup failed for Site skyai2. Database or site_config.json may be corrupted
Traceback (most recent call last):
  File "apps/frappe/frappe/commands/site.py", line 718, in backup
    odb = scheduled_backup(
  File "apps/frappe/frappe/utils/backups.py", line 532, in scheduled_backup
    odb = new_backup(
  File "apps/frappe/frappe/utils/backups.py", line 566, in new_backup
    odb = BackupGenerator(
  File "apps/frappe/frappe/utils/backups.py", line 84, in __init__
    self.setup_backup_tables()
  File "apps/frappe/frappe/utils/backups.py", line 116, in setup_backup_tables
    existing_tables = frappe.db.get_tables()
  File "apps/frappe/frappe/database/mariadb/database.py", line 439, in get_tables
    frappe.qb.from_(information_schema.tables)
  File "apps/frappe/frappe/query_builder/utils.py", line 87, in execute_query
    result = frappe.db.sql(query, params, *args, **kwargs)  # nosemgrep
  File "apps/frappe/frappe/database/database.py", line 201, in sql
    self.connect()
  File "apps/frappe/frappe/database/database.py", line 115, in connect
    self._conn = self.get_connection()
  File "apps/frappe/frappe/database/mariadb/database.py", line 98, in get_connection
    conn = self._get_connection()
  File "apps/frappe/frappe/database/mariadb/database.py", line 104, in _get_connection
    return self.create_connection()
  File "apps/frappe/frappe/database/mariadb/database.py", line 107, in create_connection
    return pymysql.connect(**self.get_connection_settings())
  File "env/lib/python3.10/site-packages/pymysql/connections.py", line 352, in __init__
    self.connect()
  File "env/lib/python3.10/site-packages/pymysql/connections.py", line 636, in connect
    self._request_authentication()
  File "env/lib/python3.10/site-packages/pymysql/connections.py", line 911, in _request_authentication
    auth_packet = self._read_packet()
  File "env/lib/python3.10/site-packages/pymysql/connections.py", line 729, in _read_packet
    packet.raise_for_error()
  File "env/lib/python3.10/site-packages/pymysql/protocol.py", line 221, in raise_for_error
    err.raise_mysql_exception(self._data)
  File "env/lib/python3.10/site-packages/pymysql/err.py", line 143, in raise_mysql_exception
    raise errorclass(errno, errval)
pymysql.err.OperationalError: (1045, "Access denied for user '_a4db896e4fe6001d'@'localhost' (using password: YES)")

self=$$;  ( mysqldump --single-transaction --quick --lock-tables=false -u _f3e7bb7e772b3608 -p********** _f3e7bb7e772b3608 -h 127.0.0.1 -P 3306   || kill $self )  | /usr/bin/gzip >> ./arun/private/backups/20231126_120002-arun-database.sql.gz

Backup Summary for arun at 2023-11-26 12:00:04.406383
Config  : ./arun/private/backups/20231126_120002-arun-site_config_backup.json 94.0B
Database: ./arun/private/backups/20231126_120002-arun-database.sql.gz         1.0MiB
Backup for Site arun has been successfully completed
File ./arun.com/private/backups/20231124_180004-arun_com-database.sql.gz is older than 24 hours
File ./arun.com/private/backups/20231124_120004-arun_com-database.sql.gz is older than 24 hours
File ./arun.com/private/backups/20231123_180003-arun_com-site_config_backup.json is older than 24 hours
File ./arun.com/private/backups/20231124_120004-arun_com-site_config_backup.json is older than 24 hours
File ./arun.com/private/backups/20231123_180003-arun_com-database.sql.gz is older than 24 hours
File ./arun.com/private/backups/20231124_180004-arun_com-site_config_backup.json is older than 24 hours
self=$$;  ( mysqldump --single-transaction --quick --lock-tables=false -u _0c41c377407f20a5 -p********** _0c41c377407f20a5 -h 127.0.0.1 -P 3306   || kill $self )  | /usr/bin/gzip >> ./arun.com/private/backups/20231126_120004-arun_com-database.sql.gz

Backup Summary for arun.com at 2023-11-26 12:00:06.127912
Config  : ./arun.com/private/backups/20231126_120004-arun_com-site_config_backup.json 183.0B
Database: ./arun.com/private/backups/20231126_120004-arun_com-database.sql.gz         1.2MiB
Backup for Site arun.com has been successfully completed
Backup failed for Site skyai. Database or site_config.json may be corrupted
Traceback (most recent call last):
  File "apps/frappe/frappe/commands/site.py", line 718, in backup
    odb = scheduled_backup(
  File "apps/frappe/frappe/utils/backups.py", line 532, in scheduled_backup
    odb = new_backup(
  File "apps/frappe/frappe/utils/backups.py", line 566, in new_backup
    odb = BackupGenerator(
  File "apps/frappe/frappe/utils/backups.py", line 84, in __init__
    self.setup_backup_tables()
  File "apps/frappe/frappe/utils/backups.py", line 116, in setup_backup_tables
    existing_tables = frappe.db.get_tables()
  File "apps/frappe/frappe/database/mariadb/database.py", line 439, in get_tables
    frappe.qb.from_(information_schema.tables)
  File "apps/frappe/frappe/query_builder/utils.py", line 87, in execute_query
    result = frappe.db.sql(query, params, *args, **kwargs)  # nosemgrep
  File "apps/frappe/frappe/database/database.py", line 201, in sql
    self.connect()
  File "apps/frappe/frappe/database/database.py", line 115, in connect
    self._conn = self.get_connection()
  File "apps/frappe/frappe/database/mariadb/database.py", line 98, in get_connection
    conn = self._get_connection()
  File "apps/frappe/frappe/database/mariadb/database.py", line 104, in _get_connection
    return self.create_connection()
  File "apps/frappe/frappe/database/mariadb/database.py", line 107, in create_connection
    return pymysql.connect(**self.get_connection_settings())
  File "env/lib/python3.10/site-packages/pymysql/connections.py", line 352, in __init__
    self.connect()
  File "env/lib/python3.10/site-packages/pymysql/connections.py", line 636, in connect
    self._request_authentication()
  File "env/lib/python3.10/site-packages/pymysql/connections.py", line 911, in _request_authentication
    auth_packet = self._read_packet()
  File "env/lib/python3.10/site-packages/pymysql/connections.py", line 729, in _read_packet
    packet.raise_for_error()
  File "env/lib/python3.10/site-packages/pymysql/protocol.py", line 221, in raise_for_error
    err.raise_mysql_exception(self._data)
  File "env/lib/python3.10/site-packages/pymysql/err.py", line 143, in raise_mysql_exception
    raise errorclass(errno, errval)
pymysql.err.OperationalError: (1045, "Access denied for user '_a4db896e4fe6001d'@'localhost' (using password: YES)")

Backup failed for Site skyai2. Database or site_config.json may be corrupted
Traceback (most recent call last):
  File "apps/frappe/frappe/commands/site.py", line 718, in backup
    odb = scheduled_backup(
  File "apps/frappe/frappe/utils/backups.py", line 532, in scheduled_backup
    odb = new_backup(
  File "apps/frappe/frappe/utils/backups.py", line 566, in new_backup
    odb = BackupGenerator(
  File "apps/frappe/frappe/utils/backups.py", line 84, in __init__
    self.setup_backup_tables()
  File "apps/frappe/frappe/utils/backups.py", line 116, in setup_backup_tables
    existing_tables = frappe.db.get_tables()
  File "apps/frappe/frappe/database/mariadb/database.py", line 439, in get_tables
    frappe.qb.from_(information_schema.tables)
  File "apps/frappe/frappe/query_builder/utils.py", line 87, in execute_query
    result = frappe.db.sql(query, params, *args, **kwargs)  # nosemgrep
  File "apps/frappe/frappe/database/database.py", line 201, in sql
    self.connect()
  File "apps/frappe/frappe/database/database.py", line 115, in connect
    self._conn = self.get_connection()
  File "apps/frappe/frappe/database/mariadb/database.py", line 98, in get_connection
    conn = self._get_connection()
  File "apps/frappe/frappe/database/mariadb/database.py", line 104, in _get_connection
    return self.create_connection()
  File "apps/frappe/frappe/database/mariadb/database.py", line 107, in create_connection
    return pymysql.connect(**self.get_connection_settings())
  File "env/lib/python3.10/site-packages/pymysql/connections.py", line 352, in __init__
    self.connect()
  File "env/lib/python3.10/site-packages/pymysql/connections.py", line 636, in connect
    self._request_authentication()
  File "env/lib/python3.10/site-packages/pymysql/connections.py", line 911, in _request_authentication
    auth_packet = self._read_packet()
  File "env/lib/python3.10/site-packages/pymysql/connections.py", line 729, in _read_packet
    packet.raise_for_error()
  File "env/lib/python3.10/site-packages/pymysql/protocol.py", line 221, in raise_for_error
    err.raise_mysql_exception(self._data)
  File "env/lib/python3.10/site-packages/pymysql/err.py", line 143, in raise_mysql_exception
    raise errorclass(errno, errval)
pymysql.err.OperationalError: (1045, "Access denied for user '_a4db896e4fe6001d'@'localhost' (using password: YES)")

self=$$;  ( mysqldump --single-transaction --quick --lock-tables=false -u _f3e7bb7e772b3608 -p********** _f3e7bb7e772b3608 -h 127.0.0.1 -P 3306   || kill $self )  | /usr/bin/gzip >> ./arun/private/backups/20231126_180002-arun-database.sql.gz

Backup Summary for arun at 2023-11-26 18:00:04.273964
Config  : ./arun/private/backups/20231126_180002-arun-site_config_backup.json 94.0B
Database: ./arun/private/backups/20231126_180002-arun-database.sql.gz         1.0MiB
Backup for Site arun has been successfully completed
File ./arun.com/private/backups/20231126_120004-arun_com-site_config_backup.json is recent
File ./arun.com/private/backups/20231126_120004-arun_com-database.sql.gz is recent
self=$$;  ( mysqldump --single-transaction --quick --lock-tables=false -u _0c41c377407f20a5 -p********** _0c41c377407f20a5 -h 127.0.0.1 -P 3306   || kill $self )  | /usr/bin/gzip >> ./arun.com/private/backups/20231126_180004-arun_com-database.sql.gz

Backup Summary for arun.com at 2023-11-26 18:00:06.160322
Config  : ./arun.com/private/backups/20231126_180004-arun_com-site_config_backup.json 183.0B
Database: ./arun.com/private/backups/20231126_180004-arun_com-database.sql.gz         1.2MiB
Backup for Site arun.com has been successfully completed
Backup failed for Site skyai. Database or site_config.json may be corrupted
Traceback (most recent call last):
  File "apps/frappe/frappe/commands/site.py", line 718, in backup
    odb = scheduled_backup(
  File "apps/frappe/frappe/utils/backups.py", line 532, in scheduled_backup
    odb = new_backup(
  File "apps/frappe/frappe/utils/backups.py", line 566, in new_backup
    odb = BackupGenerator(
  File "apps/frappe/frappe/utils/backups.py", line 84, in __init__
    self.setup_backup_tables()
  File "apps/frappe/frappe/utils/backups.py", line 116, in setup_backup_tables
    existing_tables = frappe.db.get_tables()
  File "apps/frappe/frappe/database/mariadb/database.py", line 439, in get_tables
    frappe.qb.from_(information_schema.tables)
  File "apps/frappe/frappe/query_builder/utils.py", line 87, in execute_query
    result = frappe.db.sql(query, params, *args, **kwargs)  # nosemgrep
  File "apps/frappe/frappe/database/database.py", line 201, in sql
    self.connect()
  File "apps/frappe/frappe/database/database.py", line 115, in connect
    self._conn = self.get_connection()
  File "apps/frappe/frappe/database/mariadb/database.py", line 98, in get_connection
    conn = self._get_connection()
  File "apps/frappe/frappe/database/mariadb/database.py", line 104, in _get_connection
    return self.create_connection()
  File "apps/frappe/frappe/database/mariadb/database.py", line 107, in create_connection
    return pymysql.connect(**self.get_connection_settings())
  File "env/lib/python3.10/site-packages/pymysql/connections.py", line 352, in __init__
    self.connect()
  File "env/lib/python3.10/site-packages/pymysql/connections.py", line 636, in connect
    self._request_authentication()
  File "env/lib/python3.10/site-packages/pymysql/connections.py", line 911, in _request_authentication
    auth_packet = self._read_packet()
  File "env/lib/python3.10/site-packages/pymysql/connections.py", line 729, in _read_packet
    packet.raise_for_error()
  File "env/lib/python3.10/site-packages/pymysql/protocol.py", line 221, in raise_for_error
    err.raise_mysql_exception(self._data)
  File "env/lib/python3.10/site-packages/pymysql/err.py", line 143, in raise_mysql_exception
    raise errorclass(errno, errval)
pymysql.err.OperationalError: (1045, "Access denied for user '_a4db896e4fe6001d'@'localhost' (using password: YES)")

Backup failed for Site skyai2. Database or site_config.json may be corrupted
Traceback (most recent call last):
  File "apps/frappe/frappe/commands/site.py", line 718, in backup
    odb = scheduled_backup(
  File "apps/frappe/frappe/utils/backups.py", line 532, in scheduled_backup
    odb = new_backup(
  File "apps/frappe/frappe/utils/backups.py", line 566, in new_backup
    odb = BackupGenerator(
  File "apps/frappe/frappe/utils/backups.py", line 84, in __init__
    self.setup_backup_tables()
  File "apps/frappe/frappe/utils/backups.py", line 116, in setup_backup_tables
    existing_tables = frappe.db.get_tables()
  File "apps/frappe/frappe/database/mariadb/database.py", line 439, in get_tables
    frappe.qb.from_(information_schema.tables)
  File "apps/frappe/frappe/query_builder/utils.py", line 87, in execute_query
    result = frappe.db.sql(query, params, *args, **kwargs)  # nosemgrep
  File "apps/frappe/frappe/database/database.py", line 201, in sql
    self.connect()
  File "apps/frappe/frappe/database/database.py", line 115, in connect
    self._conn = self.get_connection()
  File "apps/frappe/frappe/database/mariadb/database.py", line 98, in get_connection
    conn = self._get_connection()
  File "apps/frappe/frappe/database/mariadb/database.py", line 104, in _get_connection
    return self.create_connection()
  File "apps/frappe/frappe/database/mariadb/database.py", line 107, in create_connection
    return pymysql.connect(**self.get_connection_settings())
  File "env/lib/python3.10/site-packages/pymysql/connections.py", line 352, in __init__
    self.connect()
  File "env/lib/python3.10/site-packages/pymysql/connections.py", line 636, in connect
    self._request_authentication()
  File "env/lib/python3.10/site-packages/pymysql/connections.py", line 911, in _request_authentication
    auth_packet = self._read_packet()
  File "env/lib/python3.10/site-packages/pymysql/connections.py", line 729, in _read_packet
    packet.raise_for_error()
  File "env/lib/python3.10/site-packages/pymysql/protocol.py", line 221, in raise_for_error
    err.raise_mysql_exception(self._data)
  File "env/lib/python3.10/site-packages/pymysql/err.py", line 143, in raise_mysql_exception
    raise errorclass(errno, errval)
pymysql.err.OperationalError: (1045, "Access denied for user '_a4db896e4fe6001d'@'localhost' (using password: YES)")

self=$$;  ( mysqldump --single-transaction --quick --lock-tables=false -u _f3e7bb7e772b3608 -p********** _f3e7bb7e772b3608 -h 127.0.0.1 -P 3306   || kill $self )  | /usr/bin/gzip >> ./arun/private/backups/20231127_120002-arun-database.sql.gz

Backup Summary for arun at 2023-11-27 12:00:03.688099
Config  : ./arun/private/backups/20231127_120002-arun-site_config_backup.json 94.0B
Database: ./arun/private/backups/20231127_120002-arun-database.sql.gz         1.0MiB
Backup for Site arun has been successfully completed
File ./arun.com/private/backups/20231126_180004-arun_com-site_config_backup.json is recent
File ./arun.com/private/backups/20231126_180004-arun_com-database.sql.gz is recent
File ./arun.com/private/backups/20231126_120004-arun_com-site_config_backup.json is recent
File ./arun.com/private/backups/20231126_120004-arun_com-database.sql.gz is recent
self=$$;  ( mysqldump --single-transaction --quick --lock-tables=false -u _0c41c377407f20a5 -p********** _0c41c377407f20a5 -h 127.0.0.1 -P 3306   || kill $self )  | /usr/bin/gzip >> ./arun.com/private/backups/20231127_120003-arun_com-database.sql.gz

Backup Summary for arun.com at 2023-11-27 12:00:04.927364
Config  : ./arun.com/private/backups/20231127_120003-arun_com-site_config_backup.json 183.0B
Database: ./arun.com/private/backups/20231127_120003-arun_com-database.sql.gz         1.2MiB
Backup for Site arun.com has been successfully completed
Backup failed for Site skyai. Database or site_config.json may be corrupted
Traceback (most recent call last):
  File "apps/frappe/frappe/commands/site.py", line 718, in backup
    odb = scheduled_backup(
  File "apps/frappe/frappe/utils/backups.py", line 532, in scheduled_backup
    odb = new_backup(
  File "apps/frappe/frappe/utils/backups.py", line 566, in new_backup
    odb = BackupGenerator(
  File "apps/frappe/frappe/utils/backups.py", line 84, in __init__
    self.setup_backup_tables()
  File "apps/frappe/frappe/utils/backups.py", line 116, in setup_backup_tables
    existing_tables = frappe.db.get_tables()
  File "apps/frappe/frappe/database/mariadb/database.py", line 439, in get_tables
    frappe.qb.from_(information_schema.tables)
  File "apps/frappe/frappe/query_builder/utils.py", line 87, in execute_query
    result = frappe.db.sql(query, params, *args, **kwargs)  # nosemgrep
  File "apps/frappe/frappe/database/database.py", line 201, in sql
    self.connect()
  File "apps/frappe/frappe/database/database.py", line 115, in connect
    self._conn = self.get_connection()
  File "apps/frappe/frappe/database/mariadb/database.py", line 98, in get_connection
    conn = self._get_connection()
  File "apps/frappe/frappe/database/mariadb/database.py", line 104, in _get_connection
    return self.create_connection()
  File "apps/frappe/frappe/database/mariadb/database.py", line 107, in create_connection
    return pymysql.connect(**self.get_connection_settings())
  File "env/lib/python3.10/site-packages/pymysql/connections.py", line 352, in __init__
    self.connect()
  File "env/lib/python3.10/site-packages/pymysql/connections.py", line 636, in connect
    self._request_authentication()
  File "env/lib/python3.10/site-packages/pymysql/connections.py", line 911, in _request_authentication
    auth_packet = self._read_packet()
  File "env/lib/python3.10/site-packages/pymysql/connections.py", line 729, in _read_packet
    packet.raise_for_error()
  File "env/lib/python3.10/site-packages/pymysql/protocol.py", line 221, in raise_for_error
    err.raise_mysql_exception(self._data)
  File "env/lib/python3.10/site-packages/pymysql/err.py", line 143, in raise_mysql_exception
    raise errorclass(errno, errval)
pymysql.err.OperationalError: (1045, "Access denied for user '_a4db896e4fe6001d'@'localhost' (using password: YES)")

Backup failed for Site skyai2. Database or site_config.json may be corrupted
Traceback (most recent call last):
  File "apps/frappe/frappe/commands/site.py", line 718, in backup
    odb = scheduled_backup(
  File "apps/frappe/frappe/utils/backups.py", line 532, in scheduled_backup
    odb = new_backup(
  File "apps/frappe/frappe/utils/backups.py", line 566, in new_backup
    odb = BackupGenerator(
  File "apps/frappe/frappe/utils/backups.py", line 84, in __init__
    self.setup_backup_tables()
  File "apps/frappe/frappe/utils/backups.py", line 116, in setup_backup_tables
    existing_tables = frappe.db.get_tables()
  File "apps/frappe/frappe/database/mariadb/database.py", line 439, in get_tables
    frappe.qb.from_(information_schema.tables)
  File "apps/frappe/frappe/query_builder/utils.py", line 87, in execute_query
    result = frappe.db.sql(query, params, *args, **kwargs)  # nosemgrep
  File "apps/frappe/frappe/database/database.py", line 201, in sql
    self.connect()
  File "apps/frappe/frappe/database/database.py", line 115, in connect
    self._conn = self.get_connection()
  File "apps/frappe/frappe/database/mariadb/database.py", line 98, in get_connection
    conn = self._get_connection()
  File "apps/frappe/frappe/database/mariadb/database.py", line 104, in _get_connection
    return self.create_connection()
  File "apps/frappe/frappe/database/mariadb/database.py", line 107, in create_connection
    return pymysql.connect(**self.get_connection_settings())
  File "env/lib/python3.10/site-packages/pymysql/connections.py", line 352, in __init__
    self.connect()
  File "env/lib/python3.10/site-packages/pymysql/connections.py", line 636, in connect
    self._request_authentication()
  File "env/lib/python3.10/site-packages/pymysql/connections.py", line 911, in _request_authentication
    auth_packet = self._read_packet()
  File "env/lib/python3.10/site-packages/pymysql/connections.py", line 729, in _read_packet
    packet.raise_for_error()
  File "env/lib/python3.10/site-packages/pymysql/protocol.py", line 221, in raise_for_error
    err.raise_mysql_exception(self._data)
  File "env/lib/python3.10/site-packages/pymysql/err.py", line 143, in raise_mysql_exception
    raise errorclass(errno, errval)
pymysql.err.OperationalError: (1045, "Access denied for user '_a4db896e4fe6001d'@'localhost' (using password: YES)")

self=$$;  ( mysqldump --single-transaction --quick --lock-tables=false -u _f3e7bb7e772b3608 -p********** _f3e7bb7e772b3608 -h 127.0.0.1 -P 3306   || kill $self )  | /usr/bin/gzip >> ./arun/private/backups/20231127_180001-arun-database.sql.gz

Backup Summary for arun at 2023-11-27 18:00:03.587296
Config  : ./arun/private/backups/20231127_180001-arun-site_config_backup.json 94.0B
Database: ./arun/private/backups/20231127_180001-arun-database.sql.gz         1.0MiB
Backup for Site arun has been successfully completed
File ./arun.com/private/backups/20231126_180004-arun_com-site_config_backup.json is recent
File ./arun.com/private/backups/20231127_120003-arun_com-site_config_backup.json is recent
File ./arun.com/private/backups/20231126_180004-arun_com-database.sql.gz is recent
File ./arun.com/private/backups/20231127_120003-arun_com-database.sql.gz is recent
File ./arun.com/private/backups/20231126_120004-arun_com-site_config_backup.json is older than 24 hours
File ./arun.com/private/backups/20231126_120004-arun_com-database.sql.gz is older than 24 hours
self=$$;  ( mysqldump --single-transaction --quick --lock-tables=false -u _0c41c377407f20a5 -p********** _0c41c377407f20a5 -h 127.0.0.1 -P 3306   || kill $self )  | /usr/bin/gzip >> ./arun.com/private/backups/20231127_180003-arun_com-database.sql.gz

Backup Summary for arun.com at 2023-11-27 18:00:04.813582
Config  : ./arun.com/private/backups/20231127_180003-arun_com-site_config_backup.json 183.0B
Database: ./arun.com/private/backups/20231127_180003-arun_com-database.sql.gz         1.2MiB
Backup for Site arun.com has been successfully completed
Backup failed for Site skyai. Database or site_config.json may be corrupted
Traceback (most recent call last):
  File "apps/frappe/frappe/commands/site.py", line 718, in backup
    odb = scheduled_backup(
  File "apps/frappe/frappe/utils/backups.py", line 532, in scheduled_backup
    odb = new_backup(
  File "apps/frappe/frappe/utils/backups.py", line 566, in new_backup
    odb = BackupGenerator(
  File "apps/frappe/frappe/utils/backups.py", line 84, in __init__
    self.setup_backup_tables()
  File "apps/frappe/frappe/utils/backups.py", line 116, in setup_backup_tables
    existing_tables = frappe.db.get_tables()
  File "apps/frappe/frappe/database/mariadb/database.py", line 439, in get_tables
    frappe.qb.from_(information_schema.tables)
  File "apps/frappe/frappe/query_builder/utils.py", line 87, in execute_query
    result = frappe.db.sql(query, params, *args, **kwargs)  # nosemgrep
  File "apps/frappe/frappe/database/database.py", line 201, in sql
    self.connect()
  File "apps/frappe/frappe/database/database.py", line 115, in connect
    self._conn = self.get_connection()
  File "apps/frappe/frappe/database/mariadb/database.py", line 98, in get_connection
    conn = self._get_connection()
  File "apps/frappe/frappe/database/mariadb/database.py", line 104, in _get_connection
    return self.create_connection()
  File "apps/frappe/frappe/database/mariadb/database.py", line 107, in create_connection
    return pymysql.connect(**self.get_connection_settings())
  File "env/lib/python3.10/site-packages/pymysql/connections.py", line 352, in __init__
    self.connect()
  File "env/lib/python3.10/site-packages/pymysql/connections.py", line 636, in connect
    self._request_authentication()
  File "env/lib/python3.10/site-packages/pymysql/connections.py", line 911, in _request_authentication
    auth_packet = self._read_packet()
  File "env/lib/python3.10/site-packages/pymysql/connections.py", line 729, in _read_packet
    packet.raise_for_error()
  File "env/lib/python3.10/site-packages/pymysql/protocol.py", line 221, in raise_for_error
    err.raise_mysql_exception(self._data)
  File "env/lib/python3.10/site-packages/pymysql/err.py", line 143, in raise_mysql_exception
    raise errorclass(errno, errval)
pymysql.err.OperationalError: (1045, "Access denied for user '_a4db896e4fe6001d'@'localhost' (using password: YES)")

Backup failed for Site skyai2. Database or site_config.json may be corrupted
Traceback (most recent call last):
  File "apps/frappe/frappe/commands/site.py", line 718, in backup
    odb = scheduled_backup(
  File "apps/frappe/frappe/utils/backups.py", line 532, in scheduled_backup
    odb = new_backup(
  File "apps/frappe/frappe/utils/backups.py", line 566, in new_backup
    odb = BackupGenerator(
  File "apps/frappe/frappe/utils/backups.py", line 84, in __init__
    self.setup_backup_tables()
  File "apps/frappe/frappe/utils/backups.py", line 116, in setup_backup_tables
    existing_tables = frappe.db.get_tables()
  File "apps/frappe/frappe/database/mariadb/database.py", line 439, in get_tables
    frappe.qb.from_(information_schema.tables)
  File "apps/frappe/frappe/query_builder/utils.py", line 87, in execute_query
    result = frappe.db.sql(query, params, *args, **kwargs)  # nosemgrep
  File "apps/frappe/frappe/database/database.py", line 201, in sql
    self.connect()
  File "apps/frappe/frappe/database/database.py", line 115, in connect
    self._conn = self.get_connection()
  File "apps/frappe/frappe/database/mariadb/database.py", line 98, in get_connection
    conn = self._get_connection()
  File "apps/frappe/frappe/database/mariadb/database.py", line 104, in _get_connection
    return self.create_connection()
  File "apps/frappe/frappe/database/mariadb/database.py", line 107, in create_connection
    return pymysql.connect(**self.get_connection_settings())
  File "env/lib/python3.10/site-packages/pymysql/connections.py", line 352, in __init__
    self.connect()
  File "env/lib/python3.10/site-packages/pymysql/connections.py", line 636, in connect
    self._request_authentication()
  File "env/lib/python3.10/site-packages/pymysql/connections.py", line 911, in _request_authentication
    auth_packet = self._read_packet()
  File "env/lib/python3.10/site-packages/pymysql/connections.py", line 729, in _read_packet
    packet.raise_for_error()
  File "env/lib/python3.10/site-packages/pymysql/protocol.py", line 221, in raise_for_error
    err.raise_mysql_exception(self._data)
  File "env/lib/python3.10/site-packages/pymysql/err.py", line 143, in raise_mysql_exception
    raise errorclass(errno, errval)
pymysql.err.OperationalError: (1045, "Access denied for user '_a4db896e4fe6001d'@'localhost' (using password: YES)")

self=$$;  ( mysqldump --single-transaction --quick --lock-tables=false -u _f3e7bb7e772b3608 -p********** _f3e7bb7e772b3608 -h 127.0.0.1 -P 3306   || kill $self )  | /usr/bin/gzip >> ./arun/private/backups/20231128_120002-arun-database.sql.gz

Backup Summary for arun at 2023-11-28 12:00:04.253578
Config  : ./arun/private/backups/20231128_120002-arun-site_config_backup.json 94.0B
Database: ./arun/private/backups/20231128_120002-arun-database.sql.gz         1.0MiB
Backup for Site arun has been successfully completed
File ./arun.com/private/backups/20231126_180004-arun_com-site_config_backup.json is older than 24 hours
File ./arun.com/private/backups/20231127_180003-arun_com-site_config_backup.json is recent
File ./arun.com/private/backups/20231127_120003-arun_com-site_config_backup.json is recent
File ./arun.com/private/backups/20231126_180004-arun_com-database.sql.gz is older than 24 hours
File ./arun.com/private/backups/20231127_120003-arun_com-database.sql.gz is recent
File ./arun.com/private/backups/20231127_180003-arun_com-database.sql.gz is recent
self=$$;  ( mysqldump --single-transaction --quick --lock-tables=false -u _0c41c377407f20a5 -p********** _0c41c377407f20a5 -h 127.0.0.1 -P 3306   || kill $self )  | /usr/bin/gzip >> ./arun.com/private/backups/20231128_120004-arun_com-database.sql.gz

Backup Summary for arun.com at 2023-11-28 12:00:05.748059
Config  : ./arun.com/private/backups/20231128_120004-arun_com-site_config_backup.json 183.0B
Database: ./arun.com/private/backups/20231128_120004-arun_com-database.sql.gz         1.2MiB
Backup for Site arun.com has been successfully completed
Backup failed for Site skyai. Database or site_config.json may be corrupted
Traceback (most recent call last):
  File "apps/frappe/frappe/commands/site.py", line 718, in backup
    odb = scheduled_backup(
  File "apps/frappe/frappe/utils/backups.py", line 532, in scheduled_backup
    odb = new_backup(
  File "apps/frappe/frappe/utils/backups.py", line 566, in new_backup
    odb = BackupGenerator(
  File "apps/frappe/frappe/utils/backups.py", line 84, in __init__
    self.setup_backup_tables()
  File "apps/frappe/frappe/utils/backups.py", line 116, in setup_backup_tables
    existing_tables = frappe.db.get_tables()
  File "apps/frappe/frappe/database/mariadb/database.py", line 439, in get_tables
    frappe.qb.from_(information_schema.tables)
  File "apps/frappe/frappe/query_builder/utils.py", line 87, in execute_query
    result = frappe.db.sql(query, params, *args, **kwargs)  # nosemgrep
  File "apps/frappe/frappe/database/database.py", line 201, in sql
    self.connect()
  File "apps/frappe/frappe/database/database.py", line 115, in connect
    self._conn = self.get_connection()
  File "apps/frappe/frappe/database/mariadb/database.py", line 98, in get_connection
    conn = self._get_connection()
  File "apps/frappe/frappe/database/mariadb/database.py", line 104, in _get_connection
    return self.create_connection()
  File "apps/frappe/frappe/database/mariadb/database.py", line 107, in create_connection
    return pymysql.connect(**self.get_connection_settings())
  File "env/lib/python3.10/site-packages/pymysql/connections.py", line 352, in __init__
    self.connect()
  File "env/lib/python3.10/site-packages/pymysql/connections.py", line 636, in connect
    self._request_authentication()
  File "env/lib/python3.10/site-packages/pymysql/connections.py", line 911, in _request_authentication
    auth_packet = self._read_packet()
  File "env/lib/python3.10/site-packages/pymysql/connections.py", line 729, in _read_packet
    packet.raise_for_error()
  File "env/lib/python3.10/site-packages/pymysql/protocol.py", line 221, in raise_for_error
    err.raise_mysql_exception(self._data)
  File "env/lib/python3.10/site-packages/pymysql/err.py", line 143, in raise_mysql_exception
    raise errorclass(errno, errval)
pymysql.err.OperationalError: (1045, "Access denied for user '_a4db896e4fe6001d'@'localhost' (using password: YES)")

Backup failed for Site skyai2. Database or site_config.json may be corrupted
Traceback (most recent call last):
  File "apps/frappe/frappe/commands/site.py", line 718, in backup
    odb = scheduled_backup(
  File "apps/frappe/frappe/utils/backups.py", line 532, in scheduled_backup
    odb = new_backup(
  File "apps/frappe/frappe/utils/backups.py", line 566, in new_backup
    odb = BackupGenerator(
  File "apps/frappe/frappe/utils/backups.py", line 84, in __init__
    self.setup_backup_tables()
  File "apps/frappe/frappe/utils/backups.py", line 116, in setup_backup_tables
    existing_tables = frappe.db.get_tables()
  File "apps/frappe/frappe/database/mariadb/database.py", line 439, in get_tables
    frappe.qb.from_(information_schema.tables)
  File "apps/frappe/frappe/query_builder/utils.py", line 87, in execute_query
    result = frappe.db.sql(query, params, *args, **kwargs)  # nosemgrep
  File "apps/frappe/frappe/database/database.py", line 201, in sql
    self.connect()
  File "apps/frappe/frappe/database/database.py", line 115, in connect
    self._conn = self.get_connection()
  File "apps/frappe/frappe/database/mariadb/database.py", line 98, in get_connection
    conn = self._get_connection()
  File "apps/frappe/frappe/database/mariadb/database.py", line 104, in _get_connection
    return self.create_connection()
  File "apps/frappe/frappe/database/mariadb/database.py", line 107, in create_connection
    return pymysql.connect(**self.get_connection_settings())
  File "env/lib/python3.10/site-packages/pymysql/connections.py", line 352, in __init__
    self.connect()
  File "env/lib/python3.10/site-packages/pymysql/connections.py", line 636, in connect
    self._request_authentication()
  File "env/lib/python3.10/site-packages/pymysql/connections.py", line 911, in _request_authentication
    auth_packet = self._read_packet()
  File "env/lib/python3.10/site-packages/pymysql/connections.py", line 729, in _read_packet
    packet.raise_for_error()
  File "env/lib/python3.10/site-packages/pymysql/protocol.py", line 221, in raise_for_error
    err.raise_mysql_exception(self._data)
  File "env/lib/python3.10/site-packages/pymysql/err.py", line 143, in raise_mysql_exception
    raise errorclass(errno, errval)
pymysql.err.OperationalError: (1045, "Access denied for user '_a4db896e4fe6001d'@'localhost' (using password: YES)")

self=$$;  ( mysqldump --single-transaction --quick --lock-tables=false -u _f3e7bb7e772b3608 -p********** _f3e7bb7e772b3608 -h 127.0.0.1 -P 3306   || kill $self )  | /usr/bin/gzip >> ./arun/private/backups/20231128_180001-arun-database.sql.gz

Backup Summary for arun at 2023-11-28 18:00:03.145331
Config  : ./arun/private/backups/20231128_180001-arun-site_config_backup.json 94.0B
Database: ./arun/private/backups/20231128_180001-arun-database.sql.gz         1.0MiB
Backup for Site arun has been successfully completed
File ./arun.com/private/backups/20231127_180003-arun_com-site_config_backup.json is recent
File ./arun.com/private/backups/20231127_120003-arun_com-site_config_backup.json is older than 24 hours
File ./arun.com/private/backups/20231128_120004-arun_com-database.sql.gz is recent
File ./arun.com/private/backups/20231127_120003-arun_com-database.sql.gz is older than 24 hours
File ./arun.com/private/backups/20231128_120004-arun_com-site_config_backup.json is recent
File ./arun.com/private/backups/20231127_180003-arun_com-database.sql.gz is recent
self=$$;  ( mysqldump --single-transaction --quick --lock-tables=false -u _0c41c377407f20a5 -p********** _0c41c377407f20a5 -h 127.0.0.1 -P 3306   || kill $self )  | /usr/bin/gzip >> ./arun.com/private/backups/20231128_180003-arun_com-database.sql.gz

Backup Summary for arun.com at 2023-11-28 18:00:04.916158
Config  : ./arun.com/private/backups/20231128_180003-arun_com-site_config_backup.json 183.0B
Database: ./arun.com/private/backups/20231128_180003-arun_com-database.sql.gz         1.2MiB
Backup for Site arun.com has been successfully completed
Backup failed for Site skyai. Database or site_config.json may be corrupted
Traceback (most recent call last):
  File "apps/frappe/frappe/commands/site.py", line 718, in backup
    odb = scheduled_backup(
  File "apps/frappe/frappe/utils/backups.py", line 532, in scheduled_backup
    odb = new_backup(
  File "apps/frappe/frappe/utils/backups.py", line 566, in new_backup
    odb = BackupGenerator(
  File "apps/frappe/frappe/utils/backups.py", line 84, in __init__
    self.setup_backup_tables()
  File "apps/frappe/frappe/utils/backups.py", line 116, in setup_backup_tables
    existing_tables = frappe.db.get_tables()
  File "apps/frappe/frappe/database/mariadb/database.py", line 439, in get_tables
    frappe.qb.from_(information_schema.tables)
  File "apps/frappe/frappe/query_builder/utils.py", line 87, in execute_query
    result = frappe.db.sql(query, params, *args, **kwargs)  # nosemgrep
  File "apps/frappe/frappe/database/database.py", line 201, in sql
    self.connect()
  File "apps/frappe/frappe/database/database.py", line 115, in connect
    self._conn = self.get_connection()
  File "apps/frappe/frappe/database/mariadb/database.py", line 98, in get_connection
    conn = self._get_connection()
  File "apps/frappe/frappe/database/mariadb/database.py", line 104, in _get_connection
    return self.create_connection()
  File "apps/frappe/frappe/database/mariadb/database.py", line 107, in create_connection
    return pymysql.connect(**self.get_connection_settings())
  File "env/lib/python3.10/site-packages/pymysql/connections.py", line 352, in __init__
    self.connect()
  File "env/lib/python3.10/site-packages/pymysql/connections.py", line 636, in connect
    self._request_authentication()
  File "env/lib/python3.10/site-packages/pymysql/connections.py", line 911, in _request_authentication
    auth_packet = self._read_packet()
  File "env/lib/python3.10/site-packages/pymysql/connections.py", line 729, in _read_packet
    packet.raise_for_error()
  File "env/lib/python3.10/site-packages/pymysql/protocol.py", line 221, in raise_for_error
    err.raise_mysql_exception(self._data)
  File "env/lib/python3.10/site-packages/pymysql/err.py", line 143, in raise_mysql_exception
    raise errorclass(errno, errval)
pymysql.err.OperationalError: (1045, "Access denied for user '_a4db896e4fe6001d'@'localhost' (using password: YES)")

Backup failed for Site skyai2. Database or site_config.json may be corrupted
Traceback (most recent call last):
  File "apps/frappe/frappe/commands/site.py", line 718, in backup
    odb = scheduled_backup(
  File "apps/frappe/frappe/utils/backups.py", line 532, in scheduled_backup
    odb = new_backup(
  File "apps/frappe/frappe/utils/backups.py", line 566, in new_backup
    odb = BackupGenerator(
  File "apps/frappe/frappe/utils/backups.py", line 84, in __init__
    self.setup_backup_tables()
  File "apps/frappe/frappe/utils/backups.py", line 116, in setup_backup_tables
    existing_tables = frappe.db.get_tables()
  File "apps/frappe/frappe/database/mariadb/database.py", line 439, in get_tables
    frappe.qb.from_(information_schema.tables)
  File "apps/frappe/frappe/query_builder/utils.py", line 87, in execute_query
    result = frappe.db.sql(query, params, *args, **kwargs)  # nosemgrep
  File "apps/frappe/frappe/database/database.py", line 201, in sql
    self.connect()
  File "apps/frappe/frappe/database/database.py", line 115, in connect
    self._conn = self.get_connection()
  File "apps/frappe/frappe/database/mariadb/database.py", line 98, in get_connection
    conn = self._get_connection()
  File "apps/frappe/frappe/database/mariadb/database.py", line 104, in _get_connection
    return self.create_connection()
  File "apps/frappe/frappe/database/mariadb/database.py", line 107, in create_connection
    return pymysql.connect(**self.get_connection_settings())
  File "env/lib/python3.10/site-packages/pymysql/connections.py", line 352, in __init__
    self.connect()
  File "env/lib/python3.10/site-packages/pymysql/connections.py", line 636, in connect
    self._request_authentication()
  File "env/lib/python3.10/site-packages/pymysql/connections.py", line 911, in _request_authentication
    auth_packet = self._read_packet()
  File "env/lib/python3.10/site-packages/pymysql/connections.py", line 729, in _read_packet
    packet.raise_for_error()
  File "env/lib/python3.10/site-packages/pymysql/protocol.py", line 221, in raise_for_error
    err.raise_mysql_exception(self._data)
  File "env/lib/python3.10/site-packages/pymysql/err.py", line 143, in raise_mysql_exception
    raise errorclass(errno, errval)
pymysql.err.OperationalError: (1045, "Access denied for user '_a4db896e4fe6001d'@'localhost' (using password: YES)")

self=$$;  ( mysqldump --single-transaction --quick --lock-tables=false -u _f3e7bb7e772b3608 -p********** _f3e7bb7e772b3608 -h 127.0.0.1 -P 3306   || kill $self )  | /usr/bin/gzip >> ./arun/private/backups/20231129_120002-arun-database.sql.gz

Backup Summary for arun at 2023-11-29 12:00:04.587839
Config  : ./arun/private/backups/20231129_120002-arun-site_config_backup.json 94.0B
Database: ./arun/private/backups/20231129_120002-arun-database.sql.gz         1.0MiB
Backup for Site arun has been successfully completed
File ./arun.com/private/backups/20231127_180003-arun_com-site_config_backup.json is older than 24 hours
File ./arun.com/private/backups/20231128_120004-arun_com-database.sql.gz is recent
File ./arun.com/private/backups/20231128_180003-arun_com-database.sql.gz is recent
File ./arun.com/private/backups/20231128_180003-arun_com-site_config_backup.json is recent
File ./arun.com/private/backups/20231128_120004-arun_com-site_config_backup.json is recent
File ./arun.com/private/backups/20231127_180003-arun_com-database.sql.gz is older than 24 hours
self=$$;  ( mysqldump --single-transaction --quick --lock-tables=false -u _0c41c377407f20a5 -p********** _0c41c377407f20a5 -h 127.0.0.1 -P 3306   || kill $self )  | /usr/bin/gzip >> ./arun.com/private/backups/20231129_120004-arun_com-database.sql.gz

Backup Summary for arun.com at 2023-11-29 12:00:06.393404
Config  : ./arun.com/private/backups/20231129_120004-arun_com-site_config_backup.json 183.0B
Database: ./arun.com/private/backups/20231129_120004-arun_com-database.sql.gz         1.2MiB
Backup for Site arun.com has been successfully completed
Backup failed for Site skyai. Database or site_config.json may be corrupted
Traceback (most recent call last):
  File "apps/frappe/frappe/commands/site.py", line 718, in backup
    odb = scheduled_backup(
  File "apps/frappe/frappe/utils/backups.py", line 532, in scheduled_backup
    odb = new_backup(
  File "apps/frappe/frappe/utils/backups.py", line 566, in new_backup
    odb = BackupGenerator(
  File "apps/frappe/frappe/utils/backups.py", line 84, in __init__
    self.setup_backup_tables()
  File "apps/frappe/frappe/utils/backups.py", line 116, in setup_backup_tables
    existing_tables = frappe.db.get_tables()
  File "apps/frappe/frappe/database/mariadb/database.py", line 439, in get_tables
    frappe.qb.from_(information_schema.tables)
  File "apps/frappe/frappe/query_builder/utils.py", line 87, in execute_query
    result = frappe.db.sql(query, params, *args, **kwargs)  # nosemgrep
  File "apps/frappe/frappe/database/database.py", line 201, in sql
    self.connect()
  File "apps/frappe/frappe/database/database.py", line 115, in connect
    self._conn = self.get_connection()
  File "apps/frappe/frappe/database/mariadb/database.py", line 98, in get_connection
    conn = self._get_connection()
  File "apps/frappe/frappe/database/mariadb/database.py", line 104, in _get_connection
    return self.create_connection()
  File "apps/frappe/frappe/database/mariadb/database.py", line 107, in create_connection
    return pymysql.connect(**self.get_connection_settings())
  File "env/lib/python3.10/site-packages/pymysql/connections.py", line 352, in __init__
    self.connect()
  File "env/lib/python3.10/site-packages/pymysql/connections.py", line 636, in connect
    self._request_authentication()
  File "env/lib/python3.10/site-packages/pymysql/connections.py", line 911, in _request_authentication
    auth_packet = self._read_packet()
  File "env/lib/python3.10/site-packages/pymysql/connections.py", line 729, in _read_packet
    packet.raise_for_error()
  File "env/lib/python3.10/site-packages/pymysql/protocol.py", line 221, in raise_for_error
    err.raise_mysql_exception(self._data)
  File "env/lib/python3.10/site-packages/pymysql/err.py", line 143, in raise_mysql_exception
    raise errorclass(errno, errval)
pymysql.err.OperationalError: (1045, "Access denied for user '_a4db896e4fe6001d'@'localhost' (using password: YES)")

Backup failed for Site skyai2. Database or site_config.json may be corrupted
Traceback (most recent call last):
  File "apps/frappe/frappe/commands/site.py", line 718, in backup
    odb = scheduled_backup(
  File "apps/frappe/frappe/utils/backups.py", line 532, in scheduled_backup
    odb = new_backup(
  File "apps/frappe/frappe/utils/backups.py", line 566, in new_backup
    odb = BackupGenerator(
  File "apps/frappe/frappe/utils/backups.py", line 84, in __init__
    self.setup_backup_tables()
  File "apps/frappe/frappe/utils/backups.py", line 116, in setup_backup_tables
    existing_tables = frappe.db.get_tables()
  File "apps/frappe/frappe/database/mariadb/database.py", line 439, in get_tables
    frappe.qb.from_(information_schema.tables)
  File "apps/frappe/frappe/query_builder/utils.py", line 87, in execute_query
    result = frappe.db.sql(query, params, *args, **kwargs)  # nosemgrep
  File "apps/frappe/frappe/database/database.py", line 201, in sql
    self.connect()
  File "apps/frappe/frappe/database/database.py", line 115, in connect
    self._conn = self.get_connection()
  File "apps/frappe/frappe/database/mariadb/database.py", line 98, in get_connection
    conn = self._get_connection()
  File "apps/frappe/frappe/database/mariadb/database.py", line 104, in _get_connection
    return self.create_connection()
  File "apps/frappe/frappe/database/mariadb/database.py", line 107, in create_connection
    return pymysql.connect(**self.get_connection_settings())
  File "env/lib/python3.10/site-packages/pymysql/connections.py", line 352, in __init__
    self.connect()
  File "env/lib/python3.10/site-packages/pymysql/connections.py", line 636, in connect
    self._request_authentication()
  File "env/lib/python3.10/site-packages/pymysql/connections.py", line 911, in _request_authentication
    auth_packet = self._read_packet()
  File "env/lib/python3.10/site-packages/pymysql/connections.py", line 729, in _read_packet
    packet.raise_for_error()
  File "env/lib/python3.10/site-packages/pymysql/protocol.py", line 221, in raise_for_error
    err.raise_mysql_exception(self._data)
  File "env/lib/python3.10/site-packages/pymysql/err.py", line 143, in raise_mysql_exception
    raise errorclass(errno, errval)
pymysql.err.OperationalError: (1045, "Access denied for user '_a4db896e4fe6001d'@'localhost' (using password: YES)")

self=$$;  ( mysqldump --single-transaction --quick --lock-tables=false -u _f3e7bb7e772b3608 -p********** _f3e7bb7e772b3608 -h 127.0.0.1 -P 3306   || kill $self )  | /usr/bin/gzip >> ./arun/private/backups/20231129_180002-arun-database.sql.gz

Backup Summary for arun at 2023-11-29 18:00:04.604522
Config  : ./arun/private/backups/20231129_180002-arun-site_config_backup.json 94.0B
Database: ./arun/private/backups/20231129_180002-arun-database.sql.gz         1.0MiB
Backup for Site arun has been successfully completed
File ./arun.com/private/backups/20231128_120004-arun_com-database.sql.gz is older than 24 hours
File ./arun.com/private/backups/20231129_120004-arun_com-site_config_backup.json is recent
File ./arun.com/private/backups/20231129_120004-arun_com-database.sql.gz is recent
File ./arun.com/private/backups/20231128_180003-arun_com-database.sql.gz is recent
File ./arun.com/private/backups/20231128_180003-arun_com-site_config_backup.json is recent
File ./arun.com/private/backups/20231128_120004-arun_com-site_config_backup.json is older than 24 hours
self=$$;  ( mysqldump --single-transaction --quick --lock-tables=false -u _0c41c377407f20a5 -p********** _0c41c377407f20a5 -h 127.0.0.1 -P 3306   || kill $self )  | /usr/bin/gzip >> ./arun.com/private/backups/20231129_180004-arun_com-database.sql.gz

Backup Summary for arun.com at 2023-11-29 18:00:06.232243
Config  : ./arun.com/private/backups/20231129_180004-arun_com-site_config_backup.json 183.0B
Database: ./arun.com/private/backups/20231129_180004-arun_com-database.sql.gz         1.2MiB
Backup for Site arun.com has been successfully completed
Backup failed for Site skyai. Database or site_config.json may be corrupted
Traceback (most recent call last):
  File "apps/frappe/frappe/commands/site.py", line 718, in backup
    odb = scheduled_backup(
  File "apps/frappe/frappe/utils/backups.py", line 532, in scheduled_backup
    odb = new_backup(
  File "apps/frappe/frappe/utils/backups.py", line 566, in new_backup
    odb = BackupGenerator(
  File "apps/frappe/frappe/utils/backups.py", line 84, in __init__
    self.setup_backup_tables()
  File "apps/frappe/frappe/utils/backups.py", line 116, in setup_backup_tables
    existing_tables = frappe.db.get_tables()
  File "apps/frappe/frappe/database/mariadb/database.py", line 439, in get_tables
    frappe.qb.from_(information_schema.tables)
  File "apps/frappe/frappe/query_builder/utils.py", line 87, in execute_query
    result = frappe.db.sql(query, params, *args, **kwargs)  # nosemgrep
  File "apps/frappe/frappe/database/database.py", line 201, in sql
    self.connect()
  File "apps/frappe/frappe/database/database.py", line 115, in connect
    self._conn = self.get_connection()
  File "apps/frappe/frappe/database/mariadb/database.py", line 98, in get_connection
    conn = self._get_connection()
  File "apps/frappe/frappe/database/mariadb/database.py", line 104, in _get_connection
    return self.create_connection()
  File "apps/frappe/frappe/database/mariadb/database.py", line 107, in create_connection
    return pymysql.connect(**self.get_connection_settings())
  File "env/lib/python3.10/site-packages/pymysql/connections.py", line 352, in __init__
    self.connect()
  File "env/lib/python3.10/site-packages/pymysql/connections.py", line 636, in connect
    self._request_authentication()
  File "env/lib/python3.10/site-packages/pymysql/connections.py", line 911, in _request_authentication
    auth_packet = self._read_packet()
  File "env/lib/python3.10/site-packages/pymysql/connections.py", line 729, in _read_packet
    packet.raise_for_error()
  File "env/lib/python3.10/site-packages/pymysql/protocol.py", line 221, in raise_for_error
    err.raise_mysql_exception(self._data)
  File "env/lib/python3.10/site-packages/pymysql/err.py", line 143, in raise_mysql_exception
    raise errorclass(errno, errval)
pymysql.err.OperationalError: (1045, "Access denied for user '_a4db896e4fe6001d'@'localhost' (using password: YES)")

Backup failed for Site skyai2. Database or site_config.json may be corrupted
Traceback (most recent call last):
  File "apps/frappe/frappe/commands/site.py", line 718, in backup
    odb = scheduled_backup(
  File "apps/frappe/frappe/utils/backups.py", line 532, in scheduled_backup
    odb = new_backup(
  File "apps/frappe/frappe/utils/backups.py", line 566, in new_backup
    odb = BackupGenerator(
  File "apps/frappe/frappe/utils/backups.py", line 84, in __init__
    self.setup_backup_tables()
  File "apps/frappe/frappe/utils/backups.py", line 116, in setup_backup_tables
    existing_tables = frappe.db.get_tables()
  File "apps/frappe/frappe/database/mariadb/database.py", line 439, in get_tables
    frappe.qb.from_(information_schema.tables)
  File "apps/frappe/frappe/query_builder/utils.py", line 87, in execute_query
    result = frappe.db.sql(query, params, *args, **kwargs)  # nosemgrep
  File "apps/frappe/frappe/database/database.py", line 201, in sql
    self.connect()
  File "apps/frappe/frappe/database/database.py", line 115, in connect
    self._conn = self.get_connection()
  File "apps/frappe/frappe/database/mariadb/database.py", line 98, in get_connection
    conn = self._get_connection()
  File "apps/frappe/frappe/database/mariadb/database.py", line 104, in _get_connection
    return self.create_connection()
  File "apps/frappe/frappe/database/mariadb/database.py", line 107, in create_connection
    return pymysql.connect(**self.get_connection_settings())
  File "env/lib/python3.10/site-packages/pymysql/connections.py", line 352, in __init__
    self.connect()
  File "env/lib/python3.10/site-packages/pymysql/connections.py", line 636, in connect
    self._request_authentication()
  File "env/lib/python3.10/site-packages/pymysql/connections.py", line 911, in _request_authentication
    auth_packet = self._read_packet()
  File "env/lib/python3.10/site-packages/pymysql/connections.py", line 729, in _read_packet
    packet.raise_for_error()
  File "env/lib/python3.10/site-packages/pymysql/protocol.py", line 221, in raise_for_error
    err.raise_mysql_exception(self._data)
  File "env/lib/python3.10/site-packages/pymysql/err.py", line 143, in raise_mysql_exception
    raise errorclass(errno, errval)
pymysql.err.OperationalError: (1045, "Access denied for user '_a4db896e4fe6001d'@'localhost' (using password: YES)")

self=$$;  ( mysqldump --single-transaction --quick --lock-tables=false -u _f3e7bb7e772b3608 -p********** _f3e7bb7e772b3608 -h 127.0.0.1 -P 3306   || kill $self )  | /usr/bin/gzip >> ./arun/private/backups/20231130_120002-arun-database.sql.gz

Backup Summary for arun at 2023-11-30 12:00:04.913331
Config  : ./arun/private/backups/20231130_120002-arun-site_config_backup.json 94.0B
Database: ./arun/private/backups/20231130_120002-arun-database.sql.gz         1.0MiB
Backup for Site arun has been successfully completed
File ./arun.com/private/backups/20231129_180004-arun_com-database.sql.gz is recent
File ./arun.com/private/backups/20231129_120004-arun_com-site_config_backup.json is recent
File ./arun.com/private/backups/20231129_180004-arun_com-site_config_backup.json is recent
File ./arun.com/private/backups/20231129_120004-arun_com-database.sql.gz is recent
File ./arun.com/private/backups/20231128_180003-arun_com-database.sql.gz is older than 24 hours
File ./arun.com/private/backups/20231128_180003-arun_com-site_config_backup.json is older than 24 hours
self=$$;  ( mysqldump --single-transaction --quick --lock-tables=false -u _0c41c377407f20a5 -p********** _0c41c377407f20a5 -h 127.0.0.1 -P 3306   || kill $self )  | /usr/bin/gzip >> ./arun.com/private/backups/20231130_120005-arun_com-database.sql.gz

Backup Summary for arun.com at 2023-11-30 12:00:07.104127
Config  : ./arun.com/private/backups/20231130_120005-arun_com-site_config_backup.json 183.0B
Database: ./arun.com/private/backups/20231130_120005-arun_com-database.sql.gz         1.2MiB
Backup for Site arun.com has been successfully completed
Backup failed for Site skyai. Database or site_config.json may be corrupted
Traceback (most recent call last):
  File "apps/frappe/frappe/commands/site.py", line 718, in backup
    odb = scheduled_backup(
  File "apps/frappe/frappe/utils/backups.py", line 532, in scheduled_backup
    odb = new_backup(
  File "apps/frappe/frappe/utils/backups.py", line 566, in new_backup
    odb = BackupGenerator(
  File "apps/frappe/frappe/utils/backups.py", line 84, in __init__
    self.setup_backup_tables()
  File "apps/frappe/frappe/utils/backups.py", line 116, in setup_backup_tables
    existing_tables = frappe.db.get_tables()
  File "apps/frappe/frappe/database/mariadb/database.py", line 439, in get_tables
    frappe.qb.from_(information_schema.tables)
  File "apps/frappe/frappe/query_builder/utils.py", line 87, in execute_query
    result = frappe.db.sql(query, params, *args, **kwargs)  # nosemgrep
  File "apps/frappe/frappe/database/database.py", line 201, in sql
    self.connect()
  File "apps/frappe/frappe/database/database.py", line 115, in connect
    self._conn = self.get_connection()
  File "apps/frappe/frappe/database/mariadb/database.py", line 98, in get_connection
    conn = self._get_connection()
  File "apps/frappe/frappe/database/mariadb/database.py", line 104, in _get_connection
    return self.create_connection()
  File "apps/frappe/frappe/database/mariadb/database.py", line 107, in create_connection
    return pymysql.connect(**self.get_connection_settings())
  File "env/lib/python3.10/site-packages/pymysql/connections.py", line 352, in __init__
    self.connect()
  File "env/lib/python3.10/site-packages/pymysql/connections.py", line 636, in connect
    self._request_authentication()
  File "env/lib/python3.10/site-packages/pymysql/connections.py", line 911, in _request_authentication
    auth_packet = self._read_packet()
  File "env/lib/python3.10/site-packages/pymysql/connections.py", line 729, in _read_packet
    packet.raise_for_error()
  File "env/lib/python3.10/site-packages/pymysql/protocol.py", line 221, in raise_for_error
    err.raise_mysql_exception(self._data)
  File "env/lib/python3.10/site-packages/pymysql/err.py", line 143, in raise_mysql_exception
    raise errorclass(errno, errval)
pymysql.err.OperationalError: (1045, "Access denied for user '_a4db896e4fe6001d'@'localhost' (using password: YES)")

Backup failed for Site skyai2. Database or site_config.json may be corrupted
Traceback (most recent call last):
  File "apps/frappe/frappe/commands/site.py", line 718, in backup
    odb = scheduled_backup(
  File "apps/frappe/frappe/utils/backups.py", line 532, in scheduled_backup
    odb = new_backup(
  File "apps/frappe/frappe/utils/backups.py", line 566, in new_backup
    odb = BackupGenerator(
  File "apps/frappe/frappe/utils/backups.py", line 84, in __init__
    self.setup_backup_tables()
  File "apps/frappe/frappe/utils/backups.py", line 116, in setup_backup_tables
    existing_tables = frappe.db.get_tables()
  File "apps/frappe/frappe/database/mariadb/database.py", line 439, in get_tables
    frappe.qb.from_(information_schema.tables)
  File "apps/frappe/frappe/query_builder/utils.py", line 87, in execute_query
    result = frappe.db.sql(query, params, *args, **kwargs)  # nosemgrep
  File "apps/frappe/frappe/database/database.py", line 201, in sql
    self.connect()
  File "apps/frappe/frappe/database/database.py", line 115, in connect
    self._conn = self.get_connection()
  File "apps/frappe/frappe/database/mariadb/database.py", line 98, in get_connection
    conn = self._get_connection()
  File "apps/frappe/frappe/database/mariadb/database.py", line 104, in _get_connection
    return self.create_connection()
  File "apps/frappe/frappe/database/mariadb/database.py", line 107, in create_connection
    return pymysql.connect(**self.get_connection_settings())
  File "env/lib/python3.10/site-packages/pymysql/connections.py", line 352, in __init__
    self.connect()
  File "env/lib/python3.10/site-packages/pymysql/connections.py", line 636, in connect
    self._request_authentication()
  File "env/lib/python3.10/site-packages/pymysql/connections.py", line 911, in _request_authentication
    auth_packet = self._read_packet()
  File "env/lib/python3.10/site-packages/pymysql/connections.py", line 729, in _read_packet
    packet.raise_for_error()
  File "env/lib/python3.10/site-packages/pymysql/protocol.py", line 221, in raise_for_error
    err.raise_mysql_exception(self._data)
  File "env/lib/python3.10/site-packages/pymysql/err.py", line 143, in raise_mysql_exception
    raise errorclass(errno, errval)
pymysql.err.OperationalError: (1045, "Access denied for user '_a4db896e4fe6001d'@'localhost' (using password: YES)")

self=$$;  ( mysqldump --single-transaction --quick --lock-tables=false -u _f3e7bb7e772b3608 -p********** _f3e7bb7e772b3608 -h 127.0.0.1 -P 3306   || kill $self )  | /usr/bin/gzip >> ./arun/private/backups/20231130_180002-arun-database.sql.gz

Backup Summary for arun at 2023-11-30 18:00:04.811468
Config  : ./arun/private/backups/20231130_180002-arun-site_config_backup.json 94.0B
Database: ./arun/private/backups/20231130_180002-arun-database.sql.gz         1.0MiB
Backup for Site arun has been successfully completed
File ./arun.com/private/backups/20231130_120005-arun_com-site_config_backup.json is recent
File ./arun.com/private/backups/20231130_120005-arun_com-database.sql.gz is recent
File ./arun.com/private/backups/20231129_180004-arun_com-database.sql.gz is recent
File ./arun.com/private/backups/20231129_120004-arun_com-site_config_backup.json is older than 24 hours
File ./arun.com/private/backups/20231129_180004-arun_com-site_config_backup.json is recent
File ./arun.com/private/backups/20231129_120004-arun_com-database.sql.gz is older than 24 hours
self=$$;  ( mysqldump --single-transaction --quick --lock-tables=false -u _0c41c377407f20a5 -p********** _0c41c377407f20a5 -h 127.0.0.1 -P 3306   || kill $self )  | /usr/bin/gzip >> ./arun.com/private/backups/20231130_180004-arun_com-database.sql.gz

Backup Summary for arun.com at 2023-11-30 18:00:07.042674
Config  : ./arun.com/private/backups/20231130_180004-arun_com-site_config_backup.json 183.0B
Database: ./arun.com/private/backups/20231130_180004-arun_com-database.sql.gz         1.2MiB
Backup for Site arun.com has been successfully completed
Backup failed for Site skyai. Database or site_config.json may be corrupted
Traceback (most recent call last):
  File "apps/frappe/frappe/commands/site.py", line 718, in backup
    odb = scheduled_backup(
  File "apps/frappe/frappe/utils/backups.py", line 532, in scheduled_backup
    odb = new_backup(
  File "apps/frappe/frappe/utils/backups.py", line 566, in new_backup
    odb = BackupGenerator(
  File "apps/frappe/frappe/utils/backups.py", line 84, in __init__
    self.setup_backup_tables()
  File "apps/frappe/frappe/utils/backups.py", line 116, in setup_backup_tables
    existing_tables = frappe.db.get_tables()
  File "apps/frappe/frappe/database/mariadb/database.py", line 439, in get_tables
    frappe.qb.from_(information_schema.tables)
  File "apps/frappe/frappe/query_builder/utils.py", line 87, in execute_query
    result = frappe.db.sql(query, params, *args, **kwargs)  # nosemgrep
  File "apps/frappe/frappe/database/database.py", line 201, in sql
    self.connect()
  File "apps/frappe/frappe/database/database.py", line 115, in connect
    self._conn = self.get_connection()
  File "apps/frappe/frappe/database/mariadb/database.py", line 98, in get_connection
    conn = self._get_connection()
  File "apps/frappe/frappe/database/mariadb/database.py", line 104, in _get_connection
    return self.create_connection()
  File "apps/frappe/frappe/database/mariadb/database.py", line 107, in create_connection
    return pymysql.connect(**self.get_connection_settings())
  File "env/lib/python3.10/site-packages/pymysql/connections.py", line 352, in __init__
    self.connect()
  File "env/lib/python3.10/site-packages/pymysql/connections.py", line 636, in connect
    self._request_authentication()
  File "env/lib/python3.10/site-packages/pymysql/connections.py", line 911, in _request_authentication
    auth_packet = self._read_packet()
  File "env/lib/python3.10/site-packages/pymysql/connections.py", line 729, in _read_packet
    packet.raise_for_error()
  File "env/lib/python3.10/site-packages/pymysql/protocol.py", line 221, in raise_for_error
    err.raise_mysql_exception(self._data)
  File "env/lib/python3.10/site-packages/pymysql/err.py", line 143, in raise_mysql_exception
    raise errorclass(errno, errval)
pymysql.err.OperationalError: (1045, "Access denied for user '_a4db896e4fe6001d'@'localhost' (using password: YES)")

Backup failed for Site skyai2. Database or site_config.json may be corrupted
Traceback (most recent call last):
  File "apps/frappe/frappe/commands/site.py", line 718, in backup
    odb = scheduled_backup(
  File "apps/frappe/frappe/utils/backups.py", line 532, in scheduled_backup
    odb = new_backup(
  File "apps/frappe/frappe/utils/backups.py", line 566, in new_backup
    odb = BackupGenerator(
  File "apps/frappe/frappe/utils/backups.py", line 84, in __init__
    self.setup_backup_tables()
  File "apps/frappe/frappe/utils/backups.py", line 116, in setup_backup_tables
    existing_tables = frappe.db.get_tables()
  File "apps/frappe/frappe/database/mariadb/database.py", line 439, in get_tables
    frappe.qb.from_(information_schema.tables)
  File "apps/frappe/frappe/query_builder/utils.py", line 87, in execute_query
    result = frappe.db.sql(query, params, *args, **kwargs)  # nosemgrep
  File "apps/frappe/frappe/database/database.py", line 201, in sql
    self.connect()
  File "apps/frappe/frappe/database/database.py", line 115, in connect
    self._conn = self.get_connection()
  File "apps/frappe/frappe/database/mariadb/database.py", line 98, in get_connection
    conn = self._get_connection()
  File "apps/frappe/frappe/database/mariadb/database.py", line 104, in _get_connection
    return self.create_connection()
  File "apps/frappe/frappe/database/mariadb/database.py", line 107, in create_connection
    return pymysql.connect(**self.get_connection_settings())
  File "env/lib/python3.10/site-packages/pymysql/connections.py", line 352, in __init__
    self.connect()
  File "env/lib/python3.10/site-packages/pymysql/connections.py", line 636, in connect
    self._request_authentication()
  File "env/lib/python3.10/site-packages/pymysql/connections.py", line 911, in _request_authentication
    auth_packet = self._read_packet()
  File "env/lib/python3.10/site-packages/pymysql/connections.py", line 729, in _read_packet
    packet.raise_for_error()
  File "env/lib/python3.10/site-packages/pymysql/protocol.py", line 221, in raise_for_error
    err.raise_mysql_exception(self._data)
  File "env/lib/python3.10/site-packages/pymysql/err.py", line 143, in raise_mysql_exception
    raise errorclass(errno, errval)
pymysql.err.OperationalError: (1045, "Access denied for user '_a4db896e4fe6001d'@'localhost' (using password: YES)")

self=$$;  ( mysqldump --single-transaction --quick --lock-tables=false -u _f3e7bb7e772b3608 -p********** _f3e7bb7e772b3608 -h 127.0.0.1 -P 3306   || kill $self )  | /usr/bin/gzip >> ./arun/private/backups/20231201_120002-arun-database.sql.gz

Backup Summary for arun at 2023-12-01 12:00:04.135546
Config  : ./arun/private/backups/20231201_120002-arun-site_config_backup.json 94.0B
Database: ./arun/private/backups/20231201_120002-arun-database.sql.gz         1.0MiB
Backup for Site arun has been successfully completed
File ./arun.com/private/backups/20231130_180004-arun_com-site_config_backup.json is recent
File ./arun.com/private/backups/20231130_120005-arun_com-site_config_backup.json is recent
File ./arun.com/private/backups/20231130_120005-arun_com-database.sql.gz is recent
File ./arun.com/private/backups/20231129_180004-arun_com-database.sql.gz is older than 24 hours
File ./arun.com/private/backups/20231129_180004-arun_com-site_config_backup.json is older than 24 hours
File ./arun.com/private/backups/20231130_180004-arun_com-database.sql.gz is recent
self=$$;  ( mysqldump --single-transaction --quick --lock-tables=false -u _0c41c377407f20a5 -p********** _0c41c377407f20a5 -h 127.0.0.1 -P 3306   || kill $self )  | /usr/bin/gzip >> ./arun.com/private/backups/20231201_120004-arun_com-database.sql.gz

Backup Summary for arun.com at 2023-12-01 12:00:05.540871
Config  : ./arun.com/private/backups/20231201_120004-arun_com-site_config_backup.json 183.0B
Database: ./arun.com/private/backups/20231201_120004-arun_com-database.sql.gz         1.2MiB
Backup for Site arun.com has been successfully completed
Backup failed for Site skyai. Database or site_config.json may be corrupted
Traceback (most recent call last):
  File "apps/frappe/frappe/commands/site.py", line 718, in backup
    odb = scheduled_backup(
  File "apps/frappe/frappe/utils/backups.py", line 532, in scheduled_backup
    odb = new_backup(
  File "apps/frappe/frappe/utils/backups.py", line 566, in new_backup
    odb = BackupGenerator(
  File "apps/frappe/frappe/utils/backups.py", line 84, in __init__
    self.setup_backup_tables()
  File "apps/frappe/frappe/utils/backups.py", line 116, in setup_backup_tables
    existing_tables = frappe.db.get_tables()
  File "apps/frappe/frappe/database/mariadb/database.py", line 439, in get_tables
    frappe.qb.from_(information_schema.tables)
  File "apps/frappe/frappe/query_builder/utils.py", line 87, in execute_query
    result = frappe.db.sql(query, params, *args, **kwargs)  # nosemgrep
  File "apps/frappe/frappe/database/database.py", line 201, in sql
    self.connect()
  File "apps/frappe/frappe/database/database.py", line 115, in connect
    self._conn = self.get_connection()
  File "apps/frappe/frappe/database/mariadb/database.py", line 98, in get_connection
    conn = self._get_connection()
  File "apps/frappe/frappe/database/mariadb/database.py", line 104, in _get_connection
    return self.create_connection()
  File "apps/frappe/frappe/database/mariadb/database.py", line 107, in create_connection
    return pymysql.connect(**self.get_connection_settings())
  File "env/lib/python3.10/site-packages/pymysql/connections.py", line 352, in __init__
    self.connect()
  File "env/lib/python3.10/site-packages/pymysql/connections.py", line 636, in connect
    self._request_authentication()
  File "env/lib/python3.10/site-packages/pymysql/connections.py", line 911, in _request_authentication
    auth_packet = self._read_packet()
  File "env/lib/python3.10/site-packages/pymysql/connections.py", line 729, in _read_packet
    packet.raise_for_error()
  File "env/lib/python3.10/site-packages/pymysql/protocol.py", line 221, in raise_for_error
    err.raise_mysql_exception(self._data)
  File "env/lib/python3.10/site-packages/pymysql/err.py", line 143, in raise_mysql_exception
    raise errorclass(errno, errval)
pymysql.err.OperationalError: (1045, "Access denied for user '_a4db896e4fe6001d'@'localhost' (using password: YES)")

Backup failed for Site skyai2. Database or site_config.json may be corrupted
Traceback (most recent call last):
  File "apps/frappe/frappe/commands/site.py", line 718, in backup
    odb = scheduled_backup(
  File "apps/frappe/frappe/utils/backups.py", line 532, in scheduled_backup
    odb = new_backup(
  File "apps/frappe/frappe/utils/backups.py", line 566, in new_backup
    odb = BackupGenerator(
  File "apps/frappe/frappe/utils/backups.py", line 84, in __init__
    self.setup_backup_tables()
  File "apps/frappe/frappe/utils/backups.py", line 116, in setup_backup_tables
    existing_tables = frappe.db.get_tables()
  File "apps/frappe/frappe/database/mariadb/database.py", line 439, in get_tables
    frappe.qb.from_(information_schema.tables)
  File "apps/frappe/frappe/query_builder/utils.py", line 87, in execute_query
    result = frappe.db.sql(query, params, *args, **kwargs)  # nosemgrep
  File "apps/frappe/frappe/database/database.py", line 201, in sql
    self.connect()
  File "apps/frappe/frappe/database/database.py", line 115, in connect
    self._conn = self.get_connection()
  File "apps/frappe/frappe/database/mariadb/database.py", line 98, in get_connection
    conn = self._get_connection()
  File "apps/frappe/frappe/database/mariadb/database.py", line 104, in _get_connection
    return self.create_connection()
  File "apps/frappe/frappe/database/mariadb/database.py", line 107, in create_connection
    return pymysql.connect(**self.get_connection_settings())
  File "env/lib/python3.10/site-packages/pymysql/connections.py", line 352, in __init__
    self.connect()
  File "env/lib/python3.10/site-packages/pymysql/connections.py", line 636, in connect
    self._request_authentication()
  File "env/lib/python3.10/site-packages/pymysql/connections.py", line 911, in _request_authentication
    auth_packet = self._read_packet()
  File "env/lib/python3.10/site-packages/pymysql/connections.py", line 729, in _read_packet
    packet.raise_for_error()
  File "env/lib/python3.10/site-packages/pymysql/protocol.py", line 221, in raise_for_error
    err.raise_mysql_exception(self._data)
  File "env/lib/python3.10/site-packages/pymysql/err.py", line 143, in raise_mysql_exception
    raise errorclass(errno, errval)
pymysql.err.OperationalError: (1045, "Access denied for user '_a4db896e4fe6001d'@'localhost' (using password: YES)")

self=$$;  ( mysqldump --single-transaction --quick --lock-tables=false -u _f3e7bb7e772b3608 -p********** _f3e7bb7e772b3608 -h 127.0.0.1 -P 3306   || kill $self )  | /usr/bin/gzip >> ./arun/private/backups/20231201_180002-arun-database.sql.gz

Backup Summary for arun at 2023-12-01 18:00:04.517888
Config  : ./arun/private/backups/20231201_180002-arun-site_config_backup.json 94.0B
Database: ./arun/private/backups/20231201_180002-arun-database.sql.gz         1.0MiB
Backup for Site arun has been successfully completed
File ./arun.com/private/backups/20231130_180004-arun_com-site_config_backup.json is recent
File ./arun.com/private/backups/20231130_120005-arun_com-site_config_backup.json is older than 24 hours
File ./arun.com/private/backups/20231130_120005-arun_com-database.sql.gz is older than 24 hours
File ./arun.com/private/backups/20231201_120004-arun_com-database.sql.gz is recent
File ./arun.com/private/backups/20231130_180004-arun_com-database.sql.gz is recent
File ./arun.com/private/backups/20231201_120004-arun_com-site_config_backup.json is recent
self=$$;  ( mysqldump --single-transaction --quick --lock-tables=false -u _0c41c377407f20a5 -p********** _0c41c377407f20a5 -h 127.0.0.1 -P 3306   || kill $self )  | /usr/bin/gzip >> ./arun.com/private/backups/20231201_180004-arun_com-database.sql.gz

Backup Summary for arun.com at 2023-12-01 18:00:06.246144
Config  : ./arun.com/private/backups/20231201_180004-arun_com-site_config_backup.json 183.0B
Database: ./arun.com/private/backups/20231201_180004-arun_com-database.sql.gz         1.2MiB
Backup for Site arun.com has been successfully completed
Backup failed for Site skyai. Database or site_config.json may be corrupted
Traceback (most recent call last):
  File "apps/frappe/frappe/commands/site.py", line 718, in backup
    odb = scheduled_backup(
  File "apps/frappe/frappe/utils/backups.py", line 532, in scheduled_backup
    odb = new_backup(
  File "apps/frappe/frappe/utils/backups.py", line 566, in new_backup
    odb = BackupGenerator(
  File "apps/frappe/frappe/utils/backups.py", line 84, in __init__
    self.setup_backup_tables()
  File "apps/frappe/frappe/utils/backups.py", line 116, in setup_backup_tables
    existing_tables = frappe.db.get_tables()
  File "apps/frappe/frappe/database/mariadb/database.py", line 439, in get_tables
    frappe.qb.from_(information_schema.tables)
  File "apps/frappe/frappe/query_builder/utils.py", line 87, in execute_query
    result = frappe.db.sql(query, params, *args, **kwargs)  # nosemgrep
  File "apps/frappe/frappe/database/database.py", line 201, in sql
    self.connect()
  File "apps/frappe/frappe/database/database.py", line 115, in connect
    self._conn = self.get_connection()
  File "apps/frappe/frappe/database/mariadb/database.py", line 98, in get_connection
    conn = self._get_connection()
  File "apps/frappe/frappe/database/mariadb/database.py", line 104, in _get_connection
    return self.create_connection()
  File "apps/frappe/frappe/database/mariadb/database.py", line 107, in create_connection
    return pymysql.connect(**self.get_connection_settings())
  File "env/lib/python3.10/site-packages/pymysql/connections.py", line 352, in __init__
    self.connect()
  File "env/lib/python3.10/site-packages/pymysql/connections.py", line 636, in connect
    self._request_authentication()
  File "env/lib/python3.10/site-packages/pymysql/connections.py", line 911, in _request_authentication
    auth_packet = self._read_packet()
  File "env/lib/python3.10/site-packages/pymysql/connections.py", line 729, in _read_packet
    packet.raise_for_error()
  File "env/lib/python3.10/site-packages/pymysql/protocol.py", line 221, in raise_for_error
    err.raise_mysql_exception(self._data)
  File "env/lib/python3.10/site-packages/pymysql/err.py", line 143, in raise_mysql_exception
    raise errorclass(errno, errval)
pymysql.err.OperationalError: (1045, "Access denied for user '_a4db896e4fe6001d'@'localhost' (using password: YES)")

Backup failed for Site skyai2. Database or site_config.json may be corrupted
Traceback (most recent call last):
  File "apps/frappe/frappe/commands/site.py", line 718, in backup
    odb = scheduled_backup(
  File "apps/frappe/frappe/utils/backups.py", line 532, in scheduled_backup
    odb = new_backup(
  File "apps/frappe/frappe/utils/backups.py", line 566, in new_backup
    odb = BackupGenerator(
  File "apps/frappe/frappe/utils/backups.py", line 84, in __init__
    self.setup_backup_tables()
  File "apps/frappe/frappe/utils/backups.py", line 116, in setup_backup_tables
    existing_tables = frappe.db.get_tables()
  File "apps/frappe/frappe/database/mariadb/database.py", line 439, in get_tables
    frappe.qb.from_(information_schema.tables)
  File "apps/frappe/frappe/query_builder/utils.py", line 87, in execute_query
    result = frappe.db.sql(query, params, *args, **kwargs)  # nosemgrep
  File "apps/frappe/frappe/database/database.py", line 201, in sql
    self.connect()
  File "apps/frappe/frappe/database/database.py", line 115, in connect
    self._conn = self.get_connection()
  File "apps/frappe/frappe/database/mariadb/database.py", line 98, in get_connection
    conn = self._get_connection()
  File "apps/frappe/frappe/database/mariadb/database.py", line 104, in _get_connection
    return self.create_connection()
  File "apps/frappe/frappe/database/mariadb/database.py", line 107, in create_connection
    return pymysql.connect(**self.get_connection_settings())
  File "env/lib/python3.10/site-packages/pymysql/connections.py", line 352, in __init__
    self.connect()
  File "env/lib/python3.10/site-packages/pymysql/connections.py", line 636, in connect
    self._request_authentication()
  File "env/lib/python3.10/site-packages/pymysql/connections.py", line 911, in _request_authentication
    auth_packet = self._read_packet()
  File "env/lib/python3.10/site-packages/pymysql/connections.py", line 729, in _read_packet
    packet.raise_for_error()
  File "env/lib/python3.10/site-packages/pymysql/protocol.py", line 221, in raise_for_error
    err.raise_mysql_exception(self._data)
  File "env/lib/python3.10/site-packages/pymysql/err.py", line 143, in raise_mysql_exception
    raise errorclass(errno, errval)
pymysql.err.OperationalError: (1045, "Access denied for user '_a4db896e4fe6001d'@'localhost' (using password: YES)")

self=$$;  ( mysqldump --single-transaction --quick --lock-tables=false -u _f3e7bb7e772b3608 -p********** _f3e7bb7e772b3608 -h 127.0.0.1 -P 3306   || kill $self )  | /usr/bin/gzip >> ./arun/private/backups/20231203_180002-arun-database.sql.gz

Backup Summary for arun at 2023-12-03 18:00:04.409055
Config  : ./arun/private/backups/20231203_180002-arun-site_config_backup.json 94.0B
Database: ./arun/private/backups/20231203_180002-arun-database.sql.gz         1.0MiB
Backup for Site arun has been successfully completed
File ./arun.com/private/backups/20231201_180004-arun_com-database.sql.gz is older than 24 hours
File ./arun.com/private/backups/20231130_180004-arun_com-site_config_backup.json is older than 24 hours
File ./arun.com/private/backups/20231201_120004-arun_com-database.sql.gz is older than 24 hours
File ./arun.com/private/backups/20231130_180004-arun_com-database.sql.gz is older than 24 hours
File ./arun.com/private/backups/20231201_180004-arun_com-site_config_backup.json is older than 24 hours
File ./arun.com/private/backups/20231201_120004-arun_com-site_config_backup.json is older than 24 hours
self=$$;  ( mysqldump --single-transaction --quick --lock-tables=false -u _0c41c377407f20a5 -p********** _0c41c377407f20a5 -h 127.0.0.1 -P 3306   || kill $self )  | /usr/bin/gzip >> ./arun.com/private/backups/20231203_180004-arun_com-database.sql.gz

Backup Summary for arun.com at 2023-12-03 18:00:06.186899
Config  : ./arun.com/private/backups/20231203_180004-arun_com-site_config_backup.json 183.0B
Database: ./arun.com/private/backups/20231203_180004-arun_com-database.sql.gz         1.2MiB
Backup for Site arun.com has been successfully completed
Backup failed for Site skyai. Database or site_config.json may be corrupted
Traceback (most recent call last):
  File "apps/frappe/frappe/commands/site.py", line 718, in backup
    odb = scheduled_backup(
  File "apps/frappe/frappe/utils/backups.py", line 532, in scheduled_backup
    odb = new_backup(
  File "apps/frappe/frappe/utils/backups.py", line 566, in new_backup
    odb = BackupGenerator(
  File "apps/frappe/frappe/utils/backups.py", line 84, in __init__
    self.setup_backup_tables()
  File "apps/frappe/frappe/utils/backups.py", line 116, in setup_backup_tables
    existing_tables = frappe.db.get_tables()
  File "apps/frappe/frappe/database/mariadb/database.py", line 439, in get_tables
    frappe.qb.from_(information_schema.tables)
  File "apps/frappe/frappe/query_builder/utils.py", line 87, in execute_query
    result = frappe.db.sql(query, params, *args, **kwargs)  # nosemgrep
  File "apps/frappe/frappe/database/database.py", line 201, in sql
    self.connect()
  File "apps/frappe/frappe/database/database.py", line 115, in connect
    self._conn = self.get_connection()
  File "apps/frappe/frappe/database/mariadb/database.py", line 98, in get_connection
    conn = self._get_connection()
  File "apps/frappe/frappe/database/mariadb/database.py", line 104, in _get_connection
    return self.create_connection()
  File "apps/frappe/frappe/database/mariadb/database.py", line 107, in create_connection
    return pymysql.connect(**self.get_connection_settings())
  File "env/lib/python3.10/site-packages/pymysql/connections.py", line 352, in __init__
    self.connect()
  File "env/lib/python3.10/site-packages/pymysql/connections.py", line 636, in connect
    self._request_authentication()
  File "env/lib/python3.10/site-packages/pymysql/connections.py", line 911, in _request_authentication
    auth_packet = self._read_packet()
  File "env/lib/python3.10/site-packages/pymysql/connections.py", line 729, in _read_packet
    packet.raise_for_error()
  File "env/lib/python3.10/site-packages/pymysql/protocol.py", line 221, in raise_for_error
    err.raise_mysql_exception(self._data)
  File "env/lib/python3.10/site-packages/pymysql/err.py", line 143, in raise_mysql_exception
    raise errorclass(errno, errval)
pymysql.err.OperationalError: (1045, "Access denied for user '_a4db896e4fe6001d'@'localhost' (using password: YES)")

Backup failed for Site skyai2. Database or site_config.json may be corrupted
Traceback (most recent call last):
  File "apps/frappe/frappe/commands/site.py", line 718, in backup
    odb = scheduled_backup(
  File "apps/frappe/frappe/utils/backups.py", line 532, in scheduled_backup
    odb = new_backup(
  File "apps/frappe/frappe/utils/backups.py", line 566, in new_backup
    odb = BackupGenerator(
  File "apps/frappe/frappe/utils/backups.py", line 84, in __init__
    self.setup_backup_tables()
  File "apps/frappe/frappe/utils/backups.py", line 116, in setup_backup_tables
    existing_tables = frappe.db.get_tables()
  File "apps/frappe/frappe/database/mariadb/database.py", line 439, in get_tables
    frappe.qb.from_(information_schema.tables)
  File "apps/frappe/frappe/query_builder/utils.py", line 87, in execute_query
    result = frappe.db.sql(query, params, *args, **kwargs)  # nosemgrep
  File "apps/frappe/frappe/database/database.py", line 201, in sql
    self.connect()
  File "apps/frappe/frappe/database/database.py", line 115, in connect
    self._conn = self.get_connection()
  File "apps/frappe/frappe/database/mariadb/database.py", line 98, in get_connection
    conn = self._get_connection()
  File "apps/frappe/frappe/database/mariadb/database.py", line 104, in _get_connection
    return self.create_connection()
  File "apps/frappe/frappe/database/mariadb/database.py", line 107, in create_connection
    return pymysql.connect(**self.get_connection_settings())
  File "env/lib/python3.10/site-packages/pymysql/connections.py", line 352, in __init__
    self.connect()
  File "env/lib/python3.10/site-packages/pymysql/connections.py", line 636, in connect
    self._request_authentication()
  File "env/lib/python3.10/site-packages/pymysql/connections.py", line 911, in _request_authentication
    auth_packet = self._read_packet()
  File "env/lib/python3.10/site-packages/pymysql/connections.py", line 729, in _read_packet
    packet.raise_for_error()
  File "env/lib/python3.10/site-packages/pymysql/protocol.py", line 221, in raise_for_error
    err.raise_mysql_exception(self._data)
  File "env/lib/python3.10/site-packages/pymysql/err.py", line 143, in raise_mysql_exception
    raise errorclass(errno, errval)
pymysql.err.OperationalError: (1045, "Access denied for user '_a4db896e4fe6001d'@'localhost' (using password: YES)")

self=$$;  ( mysqldump --single-transaction --quick --lock-tables=false -u _f3e7bb7e772b3608 -p********** _f3e7bb7e772b3608 -h 127.0.0.1 -P 3306   || kill $self )  | /usr/bin/gzip >> ./arun/private/backups/20231204_120002-arun-database.sql.gz

Backup Summary for arun at 2023-12-04 12:00:04.556378
Config  : ./arun/private/backups/20231204_120002-arun-site_config_backup.json 94.0B
Database: ./arun/private/backups/20231204_120002-arun-database.sql.gz         1.0MiB
Backup for Site arun has been successfully completed
File ./arun.com/private/backups/20231203_180004-arun_com-database.sql.gz is recent
File ./arun.com/private/backups/20231203_180004-arun_com-site_config_backup.json is recent
self=$$;  ( mysqldump --single-transaction --quick --lock-tables=false -u _0c41c377407f20a5 -p********** _0c41c377407f20a5 -h 127.0.0.1 -P 3306   || kill $self )  | /usr/bin/gzip >> ./arun.com/private/backups/20231204_120004-arun_com-database.sql.gz

Backup Summary for arun.com at 2023-12-04 12:00:05.950190
Config  : ./arun.com/private/backups/20231204_120004-arun_com-site_config_backup.json 183.0B
Database: ./arun.com/private/backups/20231204_120004-arun_com-database.sql.gz         1.2MiB
Backup for Site arun.com has been successfully completed
Backup failed for Site skyai. Database or site_config.json may be corrupted
Traceback (most recent call last):
  File "apps/frappe/frappe/commands/site.py", line 718, in backup
    odb = scheduled_backup(
  File "apps/frappe/frappe/utils/backups.py", line 532, in scheduled_backup
    odb = new_backup(
  File "apps/frappe/frappe/utils/backups.py", line 566, in new_backup
    odb = BackupGenerator(
  File "apps/frappe/frappe/utils/backups.py", line 84, in __init__
    self.setup_backup_tables()
  File "apps/frappe/frappe/utils/backups.py", line 116, in setup_backup_tables
    existing_tables = frappe.db.get_tables()
  File "apps/frappe/frappe/database/mariadb/database.py", line 439, in get_tables
    frappe.qb.from_(information_schema.tables)
  File "apps/frappe/frappe/query_builder/utils.py", line 87, in execute_query
    result = frappe.db.sql(query, params, *args, **kwargs)  # nosemgrep
  File "apps/frappe/frappe/database/database.py", line 201, in sql
    self.connect()
  File "apps/frappe/frappe/database/database.py", line 115, in connect
    self._conn = self.get_connection()
  File "apps/frappe/frappe/database/mariadb/database.py", line 98, in get_connection
    conn = self._get_connection()
  File "apps/frappe/frappe/database/mariadb/database.py", line 104, in _get_connection
    return self.create_connection()
  File "apps/frappe/frappe/database/mariadb/database.py", line 107, in create_connection
    return pymysql.connect(**self.get_connection_settings())
  File "env/lib/python3.10/site-packages/pymysql/connections.py", line 352, in __init__
    self.connect()
  File "env/lib/python3.10/site-packages/pymysql/connections.py", line 636, in connect
    self._request_authentication()
  File "env/lib/python3.10/site-packages/pymysql/connections.py", line 911, in _request_authentication
    auth_packet = self._read_packet()
  File "env/lib/python3.10/site-packages/pymysql/connections.py", line 729, in _read_packet
    packet.raise_for_error()
  File "env/lib/python3.10/site-packages/pymysql/protocol.py", line 221, in raise_for_error
    err.raise_mysql_exception(self._data)
  File "env/lib/python3.10/site-packages/pymysql/err.py", line 143, in raise_mysql_exception
    raise errorclass(errno, errval)
pymysql.err.OperationalError: (1045, "Access denied for user '_a4db896e4fe6001d'@'localhost' (using password: YES)")

Backup failed for Site skyai2. Database or site_config.json may be corrupted
Traceback (most recent call last):
  File "apps/frappe/frappe/commands/site.py", line 718, in backup
    odb = scheduled_backup(
  File "apps/frappe/frappe/utils/backups.py", line 532, in scheduled_backup
    odb = new_backup(
  File "apps/frappe/frappe/utils/backups.py", line 566, in new_backup
    odb = BackupGenerator(
  File "apps/frappe/frappe/utils/backups.py", line 84, in __init__
    self.setup_backup_tables()
  File "apps/frappe/frappe/utils/backups.py", line 116, in setup_backup_tables
    existing_tables = frappe.db.get_tables()
  File "apps/frappe/frappe/database/mariadb/database.py", line 439, in get_tables
    frappe.qb.from_(information_schema.tables)
  File "apps/frappe/frappe/query_builder/utils.py", line 87, in execute_query
    result = frappe.db.sql(query, params, *args, **kwargs)  # nosemgrep
  File "apps/frappe/frappe/database/database.py", line 201, in sql
    self.connect()
  File "apps/frappe/frappe/database/database.py", line 115, in connect
    self._conn = self.get_connection()
  File "apps/frappe/frappe/database/mariadb/database.py", line 98, in get_connection
    conn = self._get_connection()
  File "apps/frappe/frappe/database/mariadb/database.py", line 104, in _get_connection
    return self.create_connection()
  File "apps/frappe/frappe/database/mariadb/database.py", line 107, in create_connection
    return pymysql.connect(**self.get_connection_settings())
  File "env/lib/python3.10/site-packages/pymysql/connections.py", line 352, in __init__
    self.connect()
  File "env/lib/python3.10/site-packages/pymysql/connections.py", line 636, in connect
    self._request_authentication()
  File "env/lib/python3.10/site-packages/pymysql/connections.py", line 911, in _request_authentication
    auth_packet = self._read_packet()
  File "env/lib/python3.10/site-packages/pymysql/connections.py", line 729, in _read_packet
    packet.raise_for_error()
  File "env/lib/python3.10/site-packages/pymysql/protocol.py", line 221, in raise_for_error
    err.raise_mysql_exception(self._data)
  File "env/lib/python3.10/site-packages/pymysql/err.py", line 143, in raise_mysql_exception
    raise errorclass(errno, errval)
pymysql.err.OperationalError: (1045, "Access denied for user '_a4db896e4fe6001d'@'localhost' (using password: YES)")

self=$$;  ( mysqldump --single-transaction --quick --lock-tables=false -u _f3e7bb7e772b3608 -p********** _f3e7bb7e772b3608 -h 127.0.0.1 -P 3306   || kill $self )  | /usr/bin/gzip >> ./arun/private/backups/20231204_180001-arun-database.sql.gz

Backup Summary for arun at 2023-12-04 18:00:03.645231
Config  : ./arun/private/backups/20231204_180001-arun-site_config_backup.json 94.0B
Database: ./arun/private/backups/20231204_180001-arun-database.sql.gz         1.0MiB
Backup for Site arun has been successfully completed
File ./arun.com/private/backups/20231204_120004-arun_com-site_config_backup.json is recent
File ./arun.com/private/backups/20231204_120004-arun_com-database.sql.gz is recent
File ./arun.com/private/backups/20231203_180004-arun_com-database.sql.gz is recent
File ./arun.com/private/backups/20231203_180004-arun_com-site_config_backup.json is recent
self=$$;  ( mysqldump --single-transaction --quick --lock-tables=false -u _0c41c377407f20a5 -p********** _0c41c377407f20a5 -h 127.0.0.1 -P 3306   || kill $self )  | /usr/bin/gzip >> ./arun.com/private/backups/20231204_180003-arun_com-database.sql.gz

Backup Summary for arun.com at 2023-12-04 18:00:05.133786
Config  : ./arun.com/private/backups/20231204_180003-arun_com-site_config_backup.json 183.0B
Database: ./arun.com/private/backups/20231204_180003-arun_com-database.sql.gz         1.2MiB
Backup for Site arun.com has been successfully completed
Backup failed for Site skyai. Database or site_config.json may be corrupted
Traceback (most recent call last):
  File "apps/frappe/frappe/commands/site.py", line 718, in backup
    odb = scheduled_backup(
  File "apps/frappe/frappe/utils/backups.py", line 532, in scheduled_backup
    odb = new_backup(
  File "apps/frappe/frappe/utils/backups.py", line 566, in new_backup
    odb = BackupGenerator(
  File "apps/frappe/frappe/utils/backups.py", line 84, in __init__
    self.setup_backup_tables()
  File "apps/frappe/frappe/utils/backups.py", line 116, in setup_backup_tables
    existing_tables = frappe.db.get_tables()
  File "apps/frappe/frappe/database/mariadb/database.py", line 439, in get_tables
    frappe.qb.from_(information_schema.tables)
  File "apps/frappe/frappe/query_builder/utils.py", line 87, in execute_query
    result = frappe.db.sql(query, params, *args, **kwargs)  # nosemgrep
  File "apps/frappe/frappe/database/database.py", line 201, in sql
    self.connect()
  File "apps/frappe/frappe/database/database.py", line 115, in connect
    self._conn = self.get_connection()
  File "apps/frappe/frappe/database/mariadb/database.py", line 98, in get_connection
    conn = self._get_connection()
  File "apps/frappe/frappe/database/mariadb/database.py", line 104, in _get_connection
    return self.create_connection()
  File "apps/frappe/frappe/database/mariadb/database.py", line 107, in create_connection
    return pymysql.connect(**self.get_connection_settings())
  File "env/lib/python3.10/site-packages/pymysql/connections.py", line 352, in __init__
    self.connect()
  File "env/lib/python3.10/site-packages/pymysql/connections.py", line 636, in connect
    self._request_authentication()
  File "env/lib/python3.10/site-packages/pymysql/connections.py", line 911, in _request_authentication
    auth_packet = self._read_packet()
  File "env/lib/python3.10/site-packages/pymysql/connections.py", line 729, in _read_packet
    packet.raise_for_error()
  File "env/lib/python3.10/site-packages/pymysql/protocol.py", line 221, in raise_for_error
    err.raise_mysql_exception(self._data)
  File "env/lib/python3.10/site-packages/pymysql/err.py", line 143, in raise_mysql_exception
    raise errorclass(errno, errval)
pymysql.err.OperationalError: (1045, "Access denied for user '_a4db896e4fe6001d'@'localhost' (using password: YES)")

Backup failed for Site skyai2. Database or site_config.json may be corrupted
Traceback (most recent call last):
  File "apps/frappe/frappe/commands/site.py", line 718, in backup
    odb = scheduled_backup(
  File "apps/frappe/frappe/utils/backups.py", line 532, in scheduled_backup
    odb = new_backup(
  File "apps/frappe/frappe/utils/backups.py", line 566, in new_backup
    odb = BackupGenerator(
  File "apps/frappe/frappe/utils/backups.py", line 84, in __init__
    self.setup_backup_tables()
  File "apps/frappe/frappe/utils/backups.py", line 116, in setup_backup_tables
    existing_tables = frappe.db.get_tables()
  File "apps/frappe/frappe/database/mariadb/database.py", line 439, in get_tables
    frappe.qb.from_(information_schema.tables)
  File "apps/frappe/frappe/query_builder/utils.py", line 87, in execute_query
    result = frappe.db.sql(query, params, *args, **kwargs)  # nosemgrep
  File "apps/frappe/frappe/database/database.py", line 201, in sql
    self.connect()
  File "apps/frappe/frappe/database/database.py", line 115, in connect
    self._conn = self.get_connection()
  File "apps/frappe/frappe/database/mariadb/database.py", line 98, in get_connection
    conn = self._get_connection()
  File "apps/frappe/frappe/database/mariadb/database.py", line 104, in _get_connection
    return self.create_connection()
  File "apps/frappe/frappe/database/mariadb/database.py", line 107, in create_connection
    return pymysql.connect(**self.get_connection_settings())
  File "env/lib/python3.10/site-packages/pymysql/connections.py", line 352, in __init__
    self.connect()
  File "env/lib/python3.10/site-packages/pymysql/connections.py", line 636, in connect
    self._request_authentication()
  File "env/lib/python3.10/site-packages/pymysql/connections.py", line 911, in _request_authentication
    auth_packet = self._read_packet()
  File "env/lib/python3.10/site-packages/pymysql/connections.py", line 729, in _read_packet
    packet.raise_for_error()
  File "env/lib/python3.10/site-packages/pymysql/protocol.py", line 221, in raise_for_error
    err.raise_mysql_exception(self._data)
  File "env/lib/python3.10/site-packages/pymysql/err.py", line 143, in raise_mysql_exception
    raise errorclass(errno, errval)
pymysql.err.OperationalError: (1045, "Access denied for user '_a4db896e4fe6001d'@'localhost' (using password: YES)")

self=$$;  ( mysqldump --single-transaction --quick --lock-tables=false -u _f3e7bb7e772b3608 -p********** _f3e7bb7e772b3608 -h 127.0.0.1 -P 3306   || kill $self )  | /usr/bin/gzip >> ./arun/private/backups/20231205_120002-arun-database.sql.gz

Backup Summary for arun at 2023-12-05 12:00:04.634171
Config  : ./arun/private/backups/20231205_120002-arun-site_config_backup.json 94.0B
Database: ./arun/private/backups/20231205_120002-arun-database.sql.gz         1.0MiB
Backup for Site arun has been successfully completed
File ./arun.com/private/backups/20231204_120004-arun_com-site_config_backup.json is recent
File ./arun.com/private/backups/20231204_120004-arun_com-database.sql.gz is recent
File ./arun.com/private/backups/20231203_180004-arun_com-database.sql.gz is older than 24 hours
File ./arun.com/private/backups/20231204_180003-arun_com-database.sql.gz is recent
File ./arun.com/private/backups/20231203_180004-arun_com-site_config_backup.json is older than 24 hours
File ./arun.com/private/backups/20231204_180003-arun_com-site_config_backup.json is recent
self=$$;  ( mysqldump --single-transaction --quick --lock-tables=false -u _0c41c377407f20a5 -p********** _0c41c377407f20a5 -h 127.0.0.1 -P 3306   || kill $self )  | /usr/bin/gzip >> ./arun.com/private/backups/20231205_120004-arun_com-database.sql.gz

Backup Summary for arun.com at 2023-12-05 12:00:06.042823
Config  : ./arun.com/private/backups/20231205_120004-arun_com-site_config_backup.json 183.0B
Database: ./arun.com/private/backups/20231205_120004-arun_com-database.sql.gz         1.2MiB
Backup for Site arun.com has been successfully completed
Backup failed for Site skyai. Database or site_config.json may be corrupted
Traceback (most recent call last):
  File "apps/frappe/frappe/commands/site.py", line 718, in backup
    odb = scheduled_backup(
  File "apps/frappe/frappe/utils/backups.py", line 532, in scheduled_backup
    odb = new_backup(
  File "apps/frappe/frappe/utils/backups.py", line 566, in new_backup
    odb = BackupGenerator(
  File "apps/frappe/frappe/utils/backups.py", line 84, in __init__
    self.setup_backup_tables()
  File "apps/frappe/frappe/utils/backups.py", line 116, in setup_backup_tables
    existing_tables = frappe.db.get_tables()
  File "apps/frappe/frappe/database/mariadb/database.py", line 439, in get_tables
    frappe.qb.from_(information_schema.tables)
  File "apps/frappe/frappe/query_builder/utils.py", line 87, in execute_query
    result = frappe.db.sql(query, params, *args, **kwargs)  # nosemgrep
  File "apps/frappe/frappe/database/database.py", line 201, in sql
    self.connect()
  File "apps/frappe/frappe/database/database.py", line 115, in connect
    self._conn = self.get_connection()
  File "apps/frappe/frappe/database/mariadb/database.py", line 98, in get_connection
    conn = self._get_connection()
  File "apps/frappe/frappe/database/mariadb/database.py", line 104, in _get_connection
    return self.create_connection()
  File "apps/frappe/frappe/database/mariadb/database.py", line 107, in create_connection
    return pymysql.connect(**self.get_connection_settings())
  File "env/lib/python3.10/site-packages/pymysql/connections.py", line 352, in __init__
    self.connect()
  File "env/lib/python3.10/site-packages/pymysql/connections.py", line 636, in connect
    self._request_authentication()
  File "env/lib/python3.10/site-packages/pymysql/connections.py", line 911, in _request_authentication
    auth_packet = self._read_packet()
  File "env/lib/python3.10/site-packages/pymysql/connections.py", line 729, in _read_packet
    packet.raise_for_error()
  File "env/lib/python3.10/site-packages/pymysql/protocol.py", line 221, in raise_for_error
    err.raise_mysql_exception(self._data)
  File "env/lib/python3.10/site-packages/pymysql/err.py", line 143, in raise_mysql_exception
    raise errorclass(errno, errval)
pymysql.err.OperationalError: (1045, "Access denied for user '_a4db896e4fe6001d'@'localhost' (using password: YES)")

Backup failed for Site skyai2. Database or site_config.json may be corrupted
Traceback (most recent call last):
  File "apps/frappe/frappe/commands/site.py", line 718, in backup
    odb = scheduled_backup(
  File "apps/frappe/frappe/utils/backups.py", line 532, in scheduled_backup
    odb = new_backup(
  File "apps/frappe/frappe/utils/backups.py", line 566, in new_backup
    odb = BackupGenerator(
  File "apps/frappe/frappe/utils/backups.py", line 84, in __init__
    self.setup_backup_tables()
  File "apps/frappe/frappe/utils/backups.py", line 116, in setup_backup_tables
    existing_tables = frappe.db.get_tables()
  File "apps/frappe/frappe/database/mariadb/database.py", line 439, in get_tables
    frappe.qb.from_(information_schema.tables)
  File "apps/frappe/frappe/query_builder/utils.py", line 87, in execute_query
    result = frappe.db.sql(query, params, *args, **kwargs)  # nosemgrep
  File "apps/frappe/frappe/database/database.py", line 201, in sql
    self.connect()
  File "apps/frappe/frappe/database/database.py", line 115, in connect
    self._conn = self.get_connection()
  File "apps/frappe/frappe/database/mariadb/database.py", line 98, in get_connection
    conn = self._get_connection()
  File "apps/frappe/frappe/database/mariadb/database.py", line 104, in _get_connection
    return self.create_connection()
  File "apps/frappe/frappe/database/mariadb/database.py", line 107, in create_connection
    return pymysql.connect(**self.get_connection_settings())
  File "env/lib/python3.10/site-packages/pymysql/connections.py", line 352, in __init__
    self.connect()
  File "env/lib/python3.10/site-packages/pymysql/connections.py", line 636, in connect
    self._request_authentication()
  File "env/lib/python3.10/site-packages/pymysql/connections.py", line 911, in _request_authentication
    auth_packet = self._read_packet()
  File "env/lib/python3.10/site-packages/pymysql/connections.py", line 729, in _read_packet
    packet.raise_for_error()
  File "env/lib/python3.10/site-packages/pymysql/protocol.py", line 221, in raise_for_error
    err.raise_mysql_exception(self._data)
  File "env/lib/python3.10/site-packages/pymysql/err.py", line 143, in raise_mysql_exception
    raise errorclass(errno, errval)
pymysql.err.OperationalError: (1045, "Access denied for user '_a4db896e4fe6001d'@'localhost' (using password: YES)")

self=$$;  ( mysqldump --single-transaction --quick --lock-tables=false -u _f3e7bb7e772b3608 -p********** _f3e7bb7e772b3608 -h 127.0.0.1 -P 3306   || kill $self )  | /usr/bin/gzip >> ./arun/private/backups/20231205_180002-arun-database.sql.gz

Backup Summary for arun at 2023-12-05 18:00:04.093976
Config  : ./arun/private/backups/20231205_180002-arun-site_config_backup.json 94.0B
Database: ./arun/private/backups/20231205_180002-arun-database.sql.gz         1.0MiB
Backup for Site arun has been successfully completed
File ./arun.com/private/backups/20231204_120004-arun_com-site_config_backup.json is older than 24 hours
File ./arun.com/private/backups/20231204_120004-arun_com-database.sql.gz is older than 24 hours
File ./arun.com/private/backups/20231205_120004-arun_com-database.sql.gz is recent
File ./arun.com/private/backups/20231205_120004-arun_com-site_config_backup.json is recent
File ./arun.com/private/backups/20231204_180003-arun_com-database.sql.gz is recent
File ./arun.com/private/backups/20231204_180003-arun_com-site_config_backup.json is recent
self=$$;  ( mysqldump --single-transaction --quick --lock-tables=false -u _0c41c377407f20a5 -p********** _0c41c377407f20a5 -h 127.0.0.1 -P 3306   || kill $self )  | /usr/bin/gzip >> ./arun.com/private/backups/20231205_180004-arun_com-database.sql.gz

Backup Summary for arun.com at 2023-12-05 18:00:05.593747
Config  : ./arun.com/private/backups/20231205_180004-arun_com-site_config_backup.json 183.0B
Database: ./arun.com/private/backups/20231205_180004-arun_com-database.sql.gz         1.2MiB
Backup for Site arun.com has been successfully completed
Backup failed for Site skyai. Database or site_config.json may be corrupted
Traceback (most recent call last):
  File "apps/frappe/frappe/commands/site.py", line 718, in backup
    odb = scheduled_backup(
  File "apps/frappe/frappe/utils/backups.py", line 532, in scheduled_backup
    odb = new_backup(
  File "apps/frappe/frappe/utils/backups.py", line 566, in new_backup
    odb = BackupGenerator(
  File "apps/frappe/frappe/utils/backups.py", line 84, in __init__
    self.setup_backup_tables()
  File "apps/frappe/frappe/utils/backups.py", line 116, in setup_backup_tables
    existing_tables = frappe.db.get_tables()
  File "apps/frappe/frappe/database/mariadb/database.py", line 439, in get_tables
    frappe.qb.from_(information_schema.tables)
  File "apps/frappe/frappe/query_builder/utils.py", line 87, in execute_query
    result = frappe.db.sql(query, params, *args, **kwargs)  # nosemgrep
  File "apps/frappe/frappe/database/database.py", line 201, in sql
    self.connect()
  File "apps/frappe/frappe/database/database.py", line 115, in connect
    self._conn = self.get_connection()
  File "apps/frappe/frappe/database/mariadb/database.py", line 98, in get_connection
    conn = self._get_connection()
  File "apps/frappe/frappe/database/mariadb/database.py", line 104, in _get_connection
    return self.create_connection()
  File "apps/frappe/frappe/database/mariadb/database.py", line 107, in create_connection
    return pymysql.connect(**self.get_connection_settings())
  File "env/lib/python3.10/site-packages/pymysql/connections.py", line 352, in __init__
    self.connect()
  File "env/lib/python3.10/site-packages/pymysql/connections.py", line 636, in connect
    self._request_authentication()
  File "env/lib/python3.10/site-packages/pymysql/connections.py", line 911, in _request_authentication
    auth_packet = self._read_packet()
  File "env/lib/python3.10/site-packages/pymysql/connections.py", line 729, in _read_packet
    packet.raise_for_error()
  File "env/lib/python3.10/site-packages/pymysql/protocol.py", line 221, in raise_for_error
    err.raise_mysql_exception(self._data)
  File "env/lib/python3.10/site-packages/pymysql/err.py", line 143, in raise_mysql_exception
    raise errorclass(errno, errval)
pymysql.err.OperationalError: (1045, "Access denied for user '_a4db896e4fe6001d'@'localhost' (using password: YES)")

Backup failed for Site skyai2. Database or site_config.json may be corrupted
Traceback (most recent call last):
  File "apps/frappe/frappe/commands/site.py", line 718, in backup
    odb = scheduled_backup(
  File "apps/frappe/frappe/utils/backups.py", line 532, in scheduled_backup
    odb = new_backup(
  File "apps/frappe/frappe/utils/backups.py", line 566, in new_backup
    odb = BackupGenerator(
  File "apps/frappe/frappe/utils/backups.py", line 84, in __init__
    self.setup_backup_tables()
  File "apps/frappe/frappe/utils/backups.py", line 116, in setup_backup_tables
    existing_tables = frappe.db.get_tables()
  File "apps/frappe/frappe/database/mariadb/database.py", line 439, in get_tables
    frappe.qb.from_(information_schema.tables)
  File "apps/frappe/frappe/query_builder/utils.py", line 87, in execute_query
    result = frappe.db.sql(query, params, *args, **kwargs)  # nosemgrep
  File "apps/frappe/frappe/database/database.py", line 201, in sql
    self.connect()
  File "apps/frappe/frappe/database/database.py", line 115, in connect
    self._conn = self.get_connection()
  File "apps/frappe/frappe/database/mariadb/database.py", line 98, in get_connection
    conn = self._get_connection()
  File "apps/frappe/frappe/database/mariadb/database.py", line 104, in _get_connection
    return self.create_connection()
  File "apps/frappe/frappe/database/mariadb/database.py", line 107, in create_connection
    return pymysql.connect(**self.get_connection_settings())
  File "env/lib/python3.10/site-packages/pymysql/connections.py", line 352, in __init__
    self.connect()
  File "env/lib/python3.10/site-packages/pymysql/connections.py", line 636, in connect
    self._request_authentication()
  File "env/lib/python3.10/site-packages/pymysql/connections.py", line 911, in _request_authentication
    auth_packet = self._read_packet()
  File "env/lib/python3.10/site-packages/pymysql/connections.py", line 729, in _read_packet
    packet.raise_for_error()
  File "env/lib/python3.10/site-packages/pymysql/protocol.py", line 221, in raise_for_error
    err.raise_mysql_exception(self._data)
  File "env/lib/python3.10/site-packages/pymysql/err.py", line 143, in raise_mysql_exception
    raise errorclass(errno, errval)
pymysql.err.OperationalError: (1045, "Access denied for user '_a4db896e4fe6001d'@'localhost' (using password: YES)")

